Workbook

Sheet Hướng dẫn
A1: HƯỚNG DẪN KIỂM TRA VÀ SỬA VỊ TRÍ
A3: 1. Làm theo thứ tự Ưu tiên: Cao (nghi sai / chưa đối chiếu) → Trung bình (OpenStreetMap, hiệu chỉnh tự động) → Thấp (website ngân hàng, đã đối chiếu).
A4: 2. Bấm "Bản đồ" để xem vị trí hiện tại. Đến tận nơi hoặc đối chiếu trên ảnh vệ tinh.
A5: 3. Chọn "Kết quả kiểm tra":
A6: • Vị trí đúng – ghim đang đúng chỗ (để trống Vĩ độ / Kinh độ mới).
A7: • Sửa vị trí – điền Vĩ độ mới, Kinh độ mới (≥ 6 chữ số thập phân, vd 13.981234 / 108.004567) và Cách xác định.
A8: • Địa điểm không tồn tại – sẽ bị ẩn khỏi bản đồ.
A9: • Đã chuyển đi – sẽ được đánh dấu "nghi sai" cho tới khi có địa chỉ mới.
A10: 4. Cột "Kiểm tra" tự báo lỗi (thiếu toạ độ, toạ độ ngoài Gia Lai, đảo vĩ/kinh độ, dời quá xa). Chỉ dòng "OK" được nhập vào hệ thống.
A11: 5. Cột "Dời bao xa (m)" tự tính khoảng cách từ vị trí cũ tới vị trí mới để tự soát lại.
A13: LẤY TOẠ ĐỘ ĐÚNG CÁCH
A14: • Đo GPS tại chỗ: đứng ở cổng/lối vào, chờ điện thoại báo độ chính xác ≤ 10 m rồi mới ghi; ghi đủ số thập phân điện thoại hiển thị, không làm tròn.
... A21: Không xoá hoặc sửa cột "Mã hệ thống" – đó là khoá để nhập đúng địa điểm.

Sheet Danh sách kiểm tra
A1: KIỂM TRA VỊ TRÍ ĐỊA ĐIỂM – TP PLEIKU CŨ (trừ quán ăn): 5 phường trung tâm, Xã Biển Hồ, Xã Gào
A2: 148 địa điểm, sắp theo Ưu tiên (Cao trước). Cột XANH: thông tin hiện tại – không sửa. Cột CAM: điền kết quả kiểm tra. Xuất ngày 17/10/2026.
A4: STT | B4: Mã hệ thống | C4: Ưu tiên | D4: Tên địa điểm | E4: Danh mục | F4: Nguồn dữ liệu | G4: Địa chỉ hiện tại | H4: Phường / xã | I4: Vĩ độ hiện tại | J4: Kinh độ hiện tại | K4: Mức tin cậy hiện tại | L4: Ghi chú của hệ thống | M4: Xem vị trí hiện tại | N4: Kết quả kiểm tra | O4: Vĩ độ mới | P4: Kinh độ mới | Q4: Cách xác định | R4: Ngày kiểm tra | S4: Người kiểm tra | T4: Ghi chú | U4: Dời bao xa (m) | V4: Kiểm tra
A5: 1 | B5: 645ecf86-7c89-440b-afdf-e9b9e894ce61 | C5: Cao | D5: Đường Thông | E5: Danh lam thắng cảnh | F5: Dữ liệu gialai-travel | G5: Thôn 1, xã Nghĩa Hưng, huyện Chư Păh, tỉnh Gia Lai | H5: Phường Hội Phú | I5: 14.061869 | J5: 108.00992 | K5: Nghi sai | L5: toạ độ cách xã/phường ghi trong nguồn (Phường Hội Phú) 9.7 km, không có tham chiếu OSM | M5: Bản đồ | U5: =IF(AND(ISNUMBER(O5),ISNUMBER(P5)),ROUND(SQRT(((P5-J5)*111320*COS(RADIANS(I5)))^2+((O5-I5)*110540)^2),0),"") | V5: =IF(N5="","",IF(N5="Sửa vị trí",IF(OR(O5="",P5=""),"Thiếu vĩ độ / kinh độ mới",IF(OR(O5<12.5,O5>15,P5<107,P5>109.6),"Toạ độ ngoài Gia Lai (đảo vĩ/kinh độ?)",IF(Q5="","Chọn cách xác định",IF(U5>20000,"Dời hơn 20 km – kiểm tra lại","OK")))),IF(AND(N5<>"Sửa vị trí",OR(O5<>"",P5<>"")),"Có toạ độ mới nhưng kết quả không phải Sửa vị trí","OK")))
A6: 2 | B6: 5d9f731f-9846-45b3-8d6e-a85be68145b4 | C6: Cao | D6: Cầu Treo | E6: Danh lam thắng cảnh | F6: Dữ liệu gialai-travel | G6: Phường Thống Nhất, Pleiku, Gia Lai | H6: Phường Pleiku | I6: 14.056879 | J6: 108.00307 | K6: Nghi sai | L6: toạ độ cách xã/phường ghi trong nguồn (Phường Pleiku) 4.7 km, không có tham chiếu OSM | M6: Bản đồ | U6: =IF(AND(ISNUMBER(O6),ISNUMBER(P6)),ROUND(SQRT(((P6-J6)*111320*COS(RADIANS(I6)))^2+((O6-I6)*110540)^2),0),"") | V6: =IF(N6="","",IF(N6="Sửa vị trí",IF(OR(O6="",P6=""),"Thiếu vĩ độ / kinh độ mới",IF(OR(O6<12.5,O6>15,P6<107,P6>109.6),"Toạ độ ngoài Gia Lai (đảo vĩ/kinh độ?)",IF(Q6="","Chọn cách xác định",IF(U6>20000,"Dời hơn 20 km – kiểm tra lại","OK")))),IF(AND(N6<>"Sửa vị trí",OR(O6<>"",P6<>"")),"Có toạ độ mới nhưng kết quả không phải Sửa vị trí","OK")))
A7: 3 | B7: 323a62c4-e7e3-43dc-9246-4065b44e411b | C7: Cao | D7: Chùa Phật Tích Hùng Vương | E7: Địa danh văn hóa | F7: Dữ liệu gialai-travel | G7: Đường Quang Trung, Tp. Pleiku, Gia Lai | H7: Phường Pleiku | I7: 13.9718 | J7: 108.0423 | K7: Nghi sai | L7: toạ độ cách xã/phường ghi trong nguồn (Phường Pleiku) 1.1 km, không có tham chiếu OSM | M7: Bản đồ | U7: =IF(AND(ISNUMBER(O7),ISNUMBER(P7)),ROUND(SQRT(((P7-J7)*111320*COS(RADIANS(I7)))^2+((O7-I7)*110540)^2),0),"") | V7: =IF(N7="","",IF(N7="Sửa vị trí",IF(OR(O7="",P7=""),"Thiếu vĩ độ / kinh độ mới",IF(OR(O7<12.5,O7>15,P7<107,P7>109.6),"Toạ độ ngoài Gia Lai (đảo vĩ/kinh độ?)",IF(Q7="","Chọn cách xác định",IF(U7>20000,"Dời hơn 20 km – kiểm tra lại","OK")))),IF(AND(N7<>"Sửa vị trí",OR(O7<>"",P7<>"")),"Có toạ độ mới nhưng kết quả không phải Sửa vị trí","OK")))
A8: 4 | B8: f6de3ec8-2fcd-4ab1-84e6-3b0256fb5a26 | C8: Cao | D8: Chợ Nguyễn Trãi (chợ Bà Định) | E8: Chợ | F8: Dữ liệu gialai-travel | G8: 51 Nguyễn Trãi, Diên Hồng, Gia Lai 600000, Việt Nam | H8: Phường Diên Hồng | I8: 13.984145 | J8: 107.99373 | K8: Chưa đối chiếu | M8: Bản đồ | U8: =IF(AND(ISNUMBER(O8),ISNUMBER(P8)),ROUND(SQRT(((P8-J8)*111320*COS(RADIANS(I8)))^2+((O8-I8)*110540)^2),0),"") | V8: =IF(N8="","",IF(N8="Sửa vị trí",IF(OR(O8="",P8=""),"Thiếu vĩ độ / kinh độ mới",IF(OR(O8<12.5,O8>15,P8<107,P8>109.6),"Toạ độ ngoài Gia Lai (đảo vĩ/kinh độ?)",IF(Q8="","Chọn cách xác định",IF(U8>20000,"Dời hơn 20 km – kiểm tra lại","OK")))),IF(AND(N8<>"Sửa vị trí",OR(O8<>"",P8<>"")),"Có toạ độ mới nhưng kết quả không phải Sửa vị trí","OK")))
A9: 5 | B9: cc535157-e44f-4a5f-bfab-e02f6ded87da | C9: Cao | D9: Chợ Đêm Pleiku (Mới) | E9: Chợ | F9: Dữ liệu gialai-travel | G9: XX7Q+J7W, Trần Xuân Soạn, Diên Hồng, Gia Lai, Việt Nam | H9: Phường Diên Hồng | I9: 13.964108 | J9: 107.98821 | K9: Chưa đối chiếu | M9: Bản đồ | U9: =IF(AND(ISNUMBER(O9),ISNUMBER(P9)),ROUND(SQRT(((P9-J9)*111320*COS(RADIANS(I9)))^2+((O9-I9)*110540)^2),0),"") | V9: =IF(N9="","",IF(N9="Sửa vị trí",IF(OR(O9="",P9=""),"Thiếu vĩ độ / kinh độ mới",IF(OR(O9<12.5,O9>15,P9<107,P9>109.6),"Toạ độ ngoài Gia Lai (đảo vĩ/kinh độ?)",IF(Q9="","Chọn cách xác định",IF(U9>20000,"Dời hơn 20 km – kiểm tra lại","OK")))),IF(AND(N9<>"Sửa vị trí",OR(O9<>"",P9<>"")),"Có toạ độ mới nhưng kết quả không phải Sửa vị trí","OK")))
A10: 6 | B10: aa7c34af-5f08-4ef5-9d48-7b226ec6910b | C10: Cao | D10: Chợ Đêm Pleiku Gia Lai | E10: Chợ | F10: Dữ liệu gialai-travel | G10: 40 Nguyễn Thiện Thuật, Diên Hồng, Gia Lai 600000, Việt Nam | H10: Phường Diên Hồng | I10: 13.97878 | J10: 107.99755 | K10: Chưa đối chiếu | M10: Bản đồ | U10: =IF(AND(ISNUMBER(O10),ISNUMBER(P10)),ROUND(SQRT(((P10-J10)*111320*COS(RADIANS(I10)))^2+((O10-I10)*110540)^2),0),"") | V10: =IF(N10="","",IF(N10="Sửa vị trí",IF(OR(O10="",P10=""),"Thiếu vĩ độ / kinh độ mới",IF(OR(O10<12.5,O10>15,P10<107,P10>109.6),"Toạ độ ngoài Gia Lai (đảo vĩ/kinh độ?)",IF(Q10="","Chọn cách xác định",IF(U10>20000,"Dời hơn 20 km – kiểm tra lại","OK")))),IF(AND(N10<>"Sửa vị trí",OR(O10<>"",P10<>"")),"Có toạ độ mới nhưng kết quả không phải Sửa vị trí","OK")))
A11: 7 | B11: a08921df-0ff9-4d7c-bf84-e8316e4f2656 | C11: Cao | D11: Chợ Trà Bá | E11: Chợ | F11: Dữ liệu gialai-travel | G11: 18 Trường Chinh, Hội Phú, Gia Lai 600000, Việt Nam | H11: Phường Hội Phú | I11: 13.954041 | J11: 108.01427 | K11: Chưa đối chiếu | M11: Bản đồ | U11: =IF(AND(ISNUMBER(O11),ISNUMBER(P11)),ROUND(SQRT(((P11-J11)*111320*COS(RADIANS(I11)))^2+((O11-I11)*110540)^2),0),"") | V11: =IF(N11="","",IF(N11="Sửa vị trí",IF(OR(O11="",P11=""),"Thiếu vĩ độ / kinh độ mới",IF(OR(O11<12.5,O11>15,P11<107,P11>109.6),"Toạ độ ngoài Gia Lai (đảo vĩ/kinh độ?)",IF(Q11="","Chọn cách xác định",IF(U11>20000,"Dời hơn 20 km – kiểm tra lại","OK")))),IF(AND(N11<>"Sửa vị trí",OR(O11<>"",P11<>"")),"Có toạ độ mới nhưng kết quả không phải Sửa vị trí","OK")))
A12: 8 | B12: 2c97df02-2a2a-4371-9c4a-a15fd685824a | C12: Cao | D12: Chợ Hoa Lư mới | E12: Chợ | F12: Dữ liệu gialai-travel | G12: X2Q6+7HG, Nguyễn Bá Lân, Pleiku, Gia Lai 600000, Việt Nam | H12: Phường Pleiku | I12: 13.988266 | J12: 108.01145 | K12: Chưa đối chiếu | M12: Bản đồ | U12: =IF(AND(ISNUMBER(O12),ISNUMBER(P12)),ROUND(SQRT(((P12-J12)*111320*COS(RADIANS(I12)))^2+((O12-I12)*110540)^2),0),"") | V12: =IF(N12="","",IF(N12="Sửa vị trí",IF(OR(O12="",P12=""),"Thiếu vĩ độ / kinh độ mới",IF(OR(O12<12.5,O12>15,P12<107,P12>109.6),"Toạ độ ngoài Gia Lai (đảo vĩ/kinh độ?)",IF(Q12="","Chọn cách xác định",IF(U12>20000,"Dời hơn 20 km – kiểm tra lại","OK")))),IF(AND(N12<>"Sửa vị trí",OR(O12<>"",P12<>"")),"Có toạ độ mới nhưng kết quả không phải Sửa vị trí","OK")))
A13: 9 | B13: 844b0f98-3d3f-48f9-ae29-4f80485a6a6f | C13: Cao | D13: Chợ Thống Nhất | E13: Chợ | F13: Dữ liệu gialai-travel | G13: 192 Phạm Văn Đồng, Thống Nhất, Gia Lai 600000, Việt Nam | H13: Phường Thống Nhất | I13: 13.997023 | J13: 107.99808 | K13: Chưa đối chiếu | M13: Bản đồ | U13: =IF(AND(ISNUMBER(O13),ISNUMBER(P13)),ROUND(SQRT(((P13-J13)*111320*COS(RADIANS(I13)))^2+((O13-I13)*110540)^2),0),"") | V13: =IF(N13="","",IF(N13="Sửa vị trí",IF(OR(O13="",P13=""),"Thiếu vĩ độ / kinh độ mới",IF(OR(O13<12.5,O13>15,P13<107,P13>109.6),"Toạ độ ngoài Gia Lai (đảo vĩ/kinh độ?)",IF(Q13="","Chọn cách xác định",IF(U13>20000,"Dời hơn 20 km – kiểm tra lại","OK")))),IF(AND(N13<>"Sửa vị trí",OR(O13<>"",P13<>"")),"Có toạ độ mới nhưng kết quả không phải Sửa vị trí","OK")))
A14: 10 | B14: 533f2cc2-6337-4540-b666-c1c4a79e63c2 | C14: Cao | D14: Chợ Biển Hồ | E14: Chợ | F14: Dữ liệu gialai-travel | G14: 22P6+CV8, Biển Hồ, Gia Lai 600000, Việt Nam | H14: Xã Biển Hồ | I14: 14.036034 | J14: 108.01221 | K14: Chưa đối chiếu | M14: Bản đồ | U14: =IF(AND(ISNUMBER(O14),ISNUMBER(P14)),ROUND(SQRT(((P14-J14)*111320*COS(RADIANS(I14)))^2+((O14-I14)*110540)^2),0),"") | V14: =IF(N14="","",IF(N14="Sửa vị trí",IF(OR(O14="",P14=""),"Thiếu vĩ độ / kinh độ mới",IF(OR(O14<12.5,O14>15,P14<107,P14>109.6),"Toạ độ ngoài Gia Lai (đảo vĩ/kinh độ?)",IF(Q14="","Chọn cách xác định",IF(U14>20000,"Dời hơn 20 km – kiểm tra lại","OK")))),IF(AND(N14<>"Sửa vị trí",OR(O14<>"",P14<>"")),"Có toạ độ mới nhưng kết quả không phải Sửa vị trí","OK")))
A15: 11 | B15: bcb9373c-4431-42f3-bc9b-1a232653a56c | C15: Cao | D15: Hồ Từ Lệnh | E15: Danh lam thắng cảnh | F15: Dữ liệu gialai-travel | G15: Đường Từ Lệnh, Tp. Pleiku, Gia Lai | H15: Phường Pleiku | I15: 13.9809 | J15: 108.0215 | K15: Chưa đối chiếu | M15: Bản đồ | U15: =IF(AND(ISNUMBER(O15),ISNUMBER(P15)),ROUND(SQRT(((P15-J15)*111320*COS(RADIANS(I15)))^2+((O15-I15)*110540)^2),0),"") | V15: =IF(N15="","",IF(N15="Sửa vị trí",IF(OR(O15="",P15=""),"Thiếu vĩ độ / kinh độ mới",IF(OR(O15<12.5,O15>15,P15<107,P15>109.6),"Toạ độ ngoài Gia Lai (đảo vĩ/kinh độ?)",IF(Q15="","Chọn cách xác định",IF(U15>20000,"Dời hơn 20 km – kiểm tra lại","OK")))),IF(AND(N15<>"Sửa vị trí",OR(O15<>"",P15<>"")),"Có toạ độ mới nhưng kết quả không phải Sửa vị trí","OK")))
A16: 12 | B16: 9e96630f-5d4a-43f8-947e-9f4f6a4dff7c | C16: Cao | D16: Núi Lửa Chư Pah | E16: Danh lam thắng cảnh | F16: Dữ liệu gialai-travel | G16: Phường Pleiku, Gia Lai | H16: Phường Pleiku | I16: 13.972151 | J16: 108.02238 | K16: Chưa đối chiếu | M16: Bản đồ | U16: =IF(AND(ISNUMBER(O16),ISNUMBER(P16)),ROUND(SQRT(((P16-J16)*111320*COS(RADIANS(I16)))^2+((O16-I16)*110540)^2),0),"") | V16: =IF(N16="","",IF(N16="Sửa vị trí",IF(OR(O16="",P16=""),"Thiếu vĩ độ / kinh độ mới",IF(OR(O16<12.5,O16>15,P16<107,P16>109.6),"Toạ độ ngoài Gia Lai (đảo vĩ/kinh độ?)",IF(Q16="","Chọn cách xác định",IF(U16>20000,"Dời hơn 20 km – kiểm tra lại","OK")))),IF(AND(N16<>"Sửa vị trí",OR(O16<>"",P16<>"")),"Có toạ độ mới nhưng kết quả không phải Sửa vị trí","OK")))
A17: 13 | B17: f3ea9782-b004-4976-8a00-d3b24cef6831 | C17: Cao | D17: Biển Hồ T'Nưng | E17: Danh lam thắng cảnh | F17: Dữ liệu gialai-travel | G17: Xã Biển Hồ, thành phố Pleiku, tỉnh Gia Lai. | H17: Xã Biển Hồ | I17: 14.034813 | J17: 107.99681 | K17: Chưa đối chiếu | M17: Bản đồ | U17: =IF(AND(ISNUMBER(O17),ISNUMBER(P17)),ROUND(SQRT(((P17-J17)*111320*COS(RADIANS(I17)))^2+((O17-I17)*110540)^2),0),"") | V17: =IF(N17="","",IF(N17="Sửa vị trí",IF(OR(O17="",P17=""),"Thiếu vĩ độ / kinh độ mới",IF(OR(O17<12.5,O17>15,P17<107,P17>109.6),"Toạ độ ngoài Gia Lai (đảo vĩ/kinh độ?)",IF(Q17="","Chọn cách xác định",IF(U17>20000,"Dời hơn 20 km – kiểm tra lại","OK")))),IF(AND(N17<>"Sửa vị trí",OR(O17<>"",P17<>"")),"Có toạ độ mới nhưng kết quả không phải Sửa vị trí","OK")))
A18: 14 | B18: c6c46286-0ca9-41f9-86e2-410c49058582 | C18: Cao | D18: The Stay Home | E18: Homestay | F18: Dữ liệu gialai-travel | G18: 10 Hoàng Văn Thái, Pleiku, Gia Lai 600000, Việt Nam | H18: Phường Pleiku | I18: 13.985172 | J18: 108.01877 | K18: Chưa đối chiếu | M18: Bản đồ | U18: =IF(AND(ISNUMBER(O18),ISNUMBER(P18)),ROUND(SQRT(((P18-J18)*111320*COS(RADIANS(I18)))^2+((O18-I18)*110540)^2),0),"") | V18: =IF(N18="","",IF(N18="Sửa vị trí",IF(OR(O18="",P18=""),"Thiếu vĩ độ / kinh độ mới",IF(OR(O18<12.5,O18>15,P18<107,P18>109.6),"Toạ độ ngoài Gia Lai (đảo vĩ/kinh độ?)",IF(Q18="","Chọn cách xác định",IF(U18>20000,"Dời hơn 20 km – kiểm tra lại","OK")))),IF(AND(N18<>"Sửa vị trí",OR(O18<>"",P18<>"")),"Có toạ độ mới nhưng kết quả không phải Sửa vị trí","OK")))
A19: 15 | B19: 42917bb5-e4df-413a-9c58-6bec9e4e32c0 | C19: Cao | D19: Nhà khách T500/QĐ3 | E19: Khách sạn | F19: Dữ liệu gialai-travel | G19: 273 Lê Duẩn, An Phú, Gia Lai 600000, Việt Nam | H19: Phường An Phú | I19: 13.97259 | J19: 108.03185 | K19: Chưa đối chiếu | M19: Bản đồ | U19: =IF(AND(ISNUMBER(O19),ISNUMBER(P19)),ROUND(SQRT(((P19-J19)*111320*COS(RADIANS(I19)))^2+((O19-I19)*110540)^2),0),"") | V19: =IF(N19="","",IF(N19="Sửa vị trí",IF(OR(O19="",P19=""),"Thiếu vĩ độ / kinh độ mới",IF(OR(O19<12.5,O19>15,P19<107,P19>109.6),"Toạ độ ngoài Gia Lai (đảo vĩ/kinh độ?)",IF(Q19="","Chọn cách xác định",IF(U19>20000,"Dời hơn 20 km – kiểm tra lại","OK")))),IF(AND(N19<>"Sửa vị trí",OR(O19<>"",P19<>"")),"Có toạ độ mới nhưng kết quả không phải Sửa vị trí","OK")))
... A55: 51 | B55: 4ded9492-b35d-162c-1247-3d2148237b52 | C55: Trung bình | D55: Petrolimex | E55: Cây xăng | F55: OpenStreetMap | G55: Xã Gào, Gia Lai | H55: Xã Gào | I55: 13.919783 | J55: 108.00492 | K55: Đã đối chiếu | M55: Bản đồ | U55: =IF(AND(ISNUMBER(O55),ISNUMBER(P55)),ROUND(SQRT(((P55-J55)*111320*COS(RADIANS(I55)))^2+((O55-I55)*110540)^2),0),"") | V55: =IF(N55="","",IF(N55="Sửa vị trí",IF(OR(O55="",P55=""),"Thiếu vĩ độ / kinh độ mới",IF(OR(O55<12.5,O55>15,P55<107,P55>109.6),"Toạ độ ngoài Gia Lai (đảo vĩ/kinh độ?)",IF(Q55="","Chọn cách xác định",IF(U55>20000,"Dời hơn 20 km – kiểm tra lại","OK")))),IF(AND(N55<>"Sửa vị trí",OR(O55<>"",P55<>"")),"Có toạ độ mới nhưng kết quả không phải Sửa vị trí","OK")))
A56: 52 | B56: 8d1ff7de-5811-434d-ab2b-526e24a08f32 | C56: Trung bình | D56: Biển Hồ Pleiku | E56: Danh lam thắng cảnh | F56: Dữ liệu gialai-travel | G56: Xã Biển Hồ, TP. Pleiku, Gia Lai (cách trung tâm thành phố ~5km) | H56: Xã Biển Hồ | I56: 14.046859 | J56: 107.99601 | K56: Đã hiệu chỉnh tự động | L56: Đã hiệu chỉnh theo OpenStreetMap (node/13105153109), dời 4766 m | M56: Bản đồ | U56: =IF(AND(ISNUMBER(O56),ISNUMBER(P56)),ROUND(SQRT(((P56-J56)*111320*COS(RADIANS(I56)))^2+((O56-I56)*110540)^2),0),"") | V56: =IF(N56="","",IF(N56="Sửa vị trí",IF(OR(O56="",P56=""),"Thiếu vĩ độ / kinh độ mới",IF(OR(O56<12.5,O56>15,P56<107,P56>109.6),"Toạ độ ngoài Gia Lai (đảo vĩ/kinh độ?)",IF(Q56="","Chọn cách xác định",IF(U56>20000,"Dời hơn 20 km – kiểm tra lại","OK")))),IF(AND(N56<>"Sửa vị trí",OR(O56<>"",P56<>"")),"Có toạ độ mới nhưng kết quả không phải Sửa vị trí","OK")))
A57: 53 | B57: 7ac49226-9446-7eaf-1bf4-a089954efbfb | C57: Trung bình | D57: ABC HOTEL | E57: Khách sạn | F57: OpenStreetMap | G57: Phường Diên Hồng, Gia Lai | H57: Phường Diên Hồng | I57: 13.969184 | J57: 107.98899 | K57: Đã đối chiếu | M57: Bản đồ | U57: =IF(AND(ISNUMBER(O57),ISNUMBER(P57)),ROUND(SQRT(((P57-J57)*111320*COS(RADIANS(I57)))^2+((O57-I57)*110540)^2),0),"") | V57: =IF(N57="","",IF(N57="Sửa vị trí",IF(OR(O57="",P57=""),"Thiếu vĩ độ / kinh độ mới",IF(OR(O57<12.5,O57>15,P57<107,P57>109.6),"Toạ độ ngoài Gia Lai (đảo vĩ/kinh độ?)",IF(Q57="","Chọn cách xác định",IF(U57>20000,"Dời hơn 20 km – kiểm tra lại","OK")))),IF(AND(N57<>"Sửa vị trí",OR(O57<>"",P57<>"")),"Có toạ độ mới nhưng kết quả không phải Sửa vị trí","OK")))
A58: 54 | B58: bc7eff7a-bdf0-ee14-30ed-34d4a7d55a9d | C58: Trung bình | D58: Diora Hotel & Apartment | E58: Khách sạn | F58: OpenStreetMap | G58: Phường Diên Hồng, Gia Lai | H58: Phường Diên Hồng | I58: 13.972615 | J58: 107.98897 | K58: Đã đối chiếu | M58: Bản đồ | U58: =IF(AND(ISNUMBER(O58),ISNUMBER(P58)),ROUND(SQRT(((P58-J58)*111320*COS(RADIANS(I58)))^2+((O58-I58)*110540)^2),0),"") | V58: =IF(N58="","",IF(N58="Sửa vị trí",IF(OR(O58="",P58=""),"Thiếu vĩ độ / kinh độ mới",IF(OR(O58<12.5,O58>15,P58<107,P58>109.6),"Toạ độ ngoài Gia Lai (đảo vĩ/kinh độ?)",IF(Q58="","Chọn cách xác định",IF(U58>20000,"Dời hơn 20 km – kiểm tra lại","OK")))),IF(AND(N58<>"Sửa vị trí",OR(O58<>"",P58<>"")),"Có toạ độ mới nhưng kết quả không phải Sửa vị trí","OK")))
A59: 55 | B59: bf65e84a-1d13-f560-1026-76d4dd776701 | C59: Trung bình | D59: Duc Long Hotel 1 | E59: Khách sạn | F59: OpenStreetMap | G59: Phường Diên Hồng, Gia Lai | H59: Phường Diên Hồng | I59: 13.98012 | J59: 107.9963 | K59: Đã đối chiếu | M59: Bản đồ | U59: =IF(AND(ISNUMBER(O59),ISNUMBER(P59)),ROUND(SQRT(((P59-J59)*111320*COS(RADIANS(I59)))^2+((O59-I59)*110540)^2),0),"") | V59: =IF(N59="","",IF(N59="Sửa vị trí",IF(OR(O59="",P59=""),"Thiếu vĩ độ / kinh độ mới",IF(OR(O59<12.5,O59>15,P59<107,P59>109.6),"Toạ độ ngoài Gia Lai (đảo vĩ/kinh độ?)",IF(Q59="","Chọn cách xác định",IF(U59>20000,"Dời hơn 20 km – kiểm tra lại","OK")))),IF(AND(N59<>"Sửa vị trí",OR(O59<>"",P59<>"")),"Có toạ độ mới nhưng kết quả không phải Sửa vị trí","OK")))
A60: 56 | B60: cf8a57a7-1403-b029-42b9-22a1a71fc658 | C60: Trung bình | D60: Gia Bảo | E60: Khách sạn | F60: OpenStreetMap | G60: Phường Diên Hồng, Gia Lai | H60: Phường Diên Hồng | I60: 13.983239 | J60: 107.99105 | K60: Đã đối chiếu | M60: Bản đồ | U60: =IF(AND(ISNUMBER(O60),ISNUMBER(P60)),ROUND(SQRT(((P60-J60)*111320*COS(RADIANS(I60)))^2+((O60-I60)*110540)^2),0),"") | V60: =IF(N60="","",IF(N60="Sửa vị trí",IF(OR(O60="",P60=""),"Thiếu vĩ độ / kinh độ mới",IF(OR(O60<12.5,O60>15,P60<107,P60>109.6),"Toạ độ ngoài Gia Lai (đảo vĩ/kinh độ?)",IF(Q60="","Chọn cách xác định",IF(U60>20000,"Dời hơn 20 km – kiểm tra lại","OK")))),IF(AND(N60<>"Sửa vị trí",OR(O60<>"",P60<>"")),"Có toạ độ mới nhưng kết quả không phải Sửa vị trí","OK")))
A61: 57 | B61: b29dd809-a06d-eaaf-707d-c40e66d1f069 | C61: Trung bình | D61: KS Thanh Bình | E61: Khách sạn | F61: OpenStreetMap | G61: Phường Diên Hồng, Gia Lai | H61: Phường Diên Hồng | I61: 13.978302 | J61: 107.98699 | K61: Đã đối chiếu | M61: Bản đồ | U61: =IF(AND(ISNUMBER(O61),ISNUMBER(P61)),ROUND(SQRT(((P61-J61)*111320*COS(RADIANS(I61)))^2+((O61-I61)*110540)^2),0),"") | V61: =IF(N61="","",IF(N61="Sửa vị trí",IF(OR(O61="",P61=""),"Thiếu vĩ độ / kinh độ mới",IF(OR(O61<12.5,O61>15,P61<107,P61>109.6),"Toạ độ ngoài Gia Lai (đảo vĩ/kinh độ?)",IF(Q61="","Chọn cách xác định",IF(U61>20000,"Dời hơn 20 km – kiểm tra lại","OK")))),IF(AND(N61<>"Sửa vị trí",OR(O61<>"",P61<>"")),"Có toạ độ mới nhưng kết quả không phải Sửa vị trí","OK")))
A62: 58 | B62: 5a5ae272-5fe9-c47c-fa20-a23bdcd59098 | C62: Trung bình | D62: Khách sạn Relax | E62: Khách sạn | F62: OpenStreetMap | G62: Phường Diên Hồng, Gia Lai | H62: Phường Diên Hồng | I62: 13.980267 | J62: 107.98948 | K62: Đã đối chiếu | M62: Bản đồ | U62: =IF(AND(ISNUMBER(O62),ISNUMBER(P62)),ROUND(SQRT(((P62-J62)*111320*COS(RADIANS(I62)))^2+((O62-I62)*110540)^2),0),"") | V62: =IF(N62="","",IF(N62="Sửa vị trí",IF(OR(O62="",P62=""),"Thiếu vĩ độ / kinh độ mới",IF(OR(O62<12.5,O62>15,P62<107,P62>109.6),"Toạ độ ngoài Gia Lai (đảo vĩ/kinh độ?)",IF(Q62="","Chọn cách xác định",IF(U62>20000,"Dời hơn 20 km – kiểm tra lại","OK")))),IF(AND(N62<>"Sửa vị trí",OR(O62<>"",P62<>"")),"Có toạ độ mới nhưng kết quả không phải Sửa vị trí","OK")))
A63: 59 | B63: 506a9ebd-920d-b377-03fe-b99505438399 | C63: Trung bình | D63: Nhà khách CA tỉnh Gia Lai | E63: Khách sạn | F63: OpenStreetMap | G63: Phường Diên Hồng, Gia Lai | H63: Phường Diên Hồng | I63: 13.976554 | J63: 108.00087 | K63: Đã đối chiếu | M63: Bản đồ | U63: =IF(AND(ISNUMBER(O63),ISNUMBER(P63)),ROUND(SQRT(((P63-J63)*111320*COS(RADIANS(I63)))^2+((O63-I63)*110540)^2),0),"") | V63: =IF(N63="","",IF(N63="Sửa vị trí",IF(OR(O63="",P63=""),"Thiếu vĩ độ / kinh độ mới",IF(OR(O63<12.5,O63>15,P63<107,P63>109.6),"Toạ độ ngoài Gia Lai (đảo vĩ/kinh độ?)",IF(Q63="","Chọn cách xác định",IF(U63>20000,"Dời hơn 20 km – kiểm tra lại","OK")))),IF(AND(N63<>"Sửa vị trí",OR(O63<>"",P63<>"")),"Có toạ độ mới nhưng kết quả không phải Sửa vị trí","OK")))
A64: 60 | B64: afd9ace6-73cd-b861-d589-e9b224a774ba | C64: Trung bình | D64: Pleiku Highlands Boutique Hotel | E64: Khách sạn | F64: OpenStreetMap | G64: Phường Diên Hồng, Gia Lai | H64: Phường Diên Hồng | I64: 13.970364 | J64: 107.99958 | K64: Đã đối chiếu | M64: Bản đồ | U64: =IF(AND(ISNUMBER(O64),ISNUMBER(P64)),ROUND(SQRT(((P64-J64)*111320*COS(RADIANS(I64)))^2+((O64-I64)*110540)^2),0),"") | V64: =IF(N64="","",IF(N64="Sửa vị trí",IF(OR(O64="",P64=""),"Thiếu vĩ độ / kinh độ mới",IF(OR(O64<12.5,O64>15,P64<107,P64>109.6),"Toạ độ ngoài Gia Lai (đảo vĩ/kinh độ?)",IF(Q64="","Chọn cách xác định",IF(U64>20000,"Dời hơn 20 km – kiểm tra lại","OK")))),IF(AND(N64<>"Sửa vị trí",OR(O64<>"",P64<>"")),"Có toạ độ mới nhưng kết quả không phải Sửa vị trí","OK")))
A65: 61 | B65: 6c5840c4-1de3-a30a-494d-8530bd929e56 | C65: Trung bình | D65: Tre Xanh Hotel | E65: Khách sạn | F65: OpenStreetMap | G65: 9 Hai Bà Trưng, Phường Diên Hồng, Gia Lai | H65: Phường Diên Hồng | I65: 13.979965 | J65: 107.99863 | K65: Đã đối chiếu | M65: Bản đồ | U65: =IF(AND(ISNUMBER(O65),ISNUMBER(P65)),ROUND(SQRT(((P65-J65)*111320*COS(RADIANS(I65)))^2+((O65-I65)*110540)^2),0),"") | V65: =IF(N65="","",IF(N65="Sửa vị trí",IF(OR(O65="",P65=""),"Thiếu vĩ độ / kinh độ mới",IF(OR(O65<12.5,O65>15,P65<107,P65>109.6),"Toạ độ ngoài Gia Lai (đảo vĩ/kinh độ?)",IF(Q65="","Chọn cách xác định",IF(U65>20000,"Dời hơn 20 km – kiểm tra lại","OK")))),IF(AND(N65<>"Sửa vị trí",OR(O65<>"",P65<>"")),"Có toạ độ mới nhưng kết quả không phải Sửa vị trí","OK")))
A66: 62 | B66: 694141ba-3545-ff24-2b20-42b57bc28313 | C66: Trung bình | D66: Tre Xanh Hotel | E66: Khách sạn | F66: OpenStreetMap | G66: 9 Hai Bà Trưng, Phường Diên Hồng, Gia Lai | H66: Phường Diên Hồng | I66: 13.97996 | J66: 107.99865 | K66: Đã đối chiếu | M66: Bản đồ | U66: =IF(AND(ISNUMBER(O66),ISNUMBER(P66)),ROUND(SQRT(((P66-J66)*111320*COS(RADIANS(I66)))^2+((O66-I66)*110540)^2),0),"") | V66: =IF(N66="","",IF(N66="Sửa vị trí",IF(OR(O66="",P66=""),"Thiếu vĩ độ / kinh độ mới",IF(OR(O66<12.5,O66>15,P66<107,P66>109.6),"Toạ độ ngoài Gia Lai (đảo vĩ/kinh độ?)",IF(Q66="","Chọn cách xác định",IF(U66>20000,"Dời hơn 20 km – kiểm tra lại","OK")))),IF(AND(N66<>"Sửa vị trí",OR(O66<>"",P66<>"")),"Có toạ độ mới nhưng kết quả không phải Sửa vị trí","OK")))
A67: 63 | B67: 29c87873-ddef-1fb3-3e1c-05f62d5d0eee | C67: Trung bình | D67: Hoài Thương Hotel | E67: Khách sạn | F67: OpenStreetMap | G67: Phường Hội Phú, Gia Lai | H67: Phường Hội Phú | I67: 13.964694 | J67: 108.0173 | K67: Đã đối chiếu | M67: Bản đồ | U67: =IF(AND(ISNUMBER(O67),ISNUMBER(P67)),ROUND(SQRT(((P67-J67)*111320*COS(RADIANS(I67)))^2+((O67-I67)*110540)^2),0),"") | V67: =IF(N67="","",IF(N67="Sửa vị trí",IF(OR(O67="",P67=""),"Thiếu vĩ độ / kinh độ mới",IF(OR(O67<12.5,O67>15,P67<107,P67>109.6),"Toạ độ ngoài Gia Lai (đảo vĩ/kinh độ?)",IF(Q67="","Chọn cách xác định",IF(U67>20000,"Dời hơn 20 km – kiểm tra lại","OK")))),IF(AND(N67<>"Sửa vị trí",OR(O67<>"",P67<>"")),"Có toạ độ mới nhưng kết quả không phải Sửa vị trí","OK")))
A68: 64 | B68: 2e83abe8-662d-41aa-965f-fd5f0027f508 | C68: Trung bình | D68: Khách Sạn Minh Mạnh | E68: Khách sạn | F68: OpenStreetMap | G68: Phường Hội Phú, Gia Lai | H68: Phường Hội Phú | I68: 13.963553 | J68: 108.0205 | K68: Đã đối chiếu | M68: Bản đồ | U68: =IF(AND(ISNUMBER(O68),ISNUMBER(P68)),ROUND(SQRT(((P68-J68)*111320*COS(RADIANS(I68)))^2+((O68-I68)*110540)^2),0),"") | V68: =IF(N68="","",IF(N68="Sửa vị trí",IF(OR(O68="",P68=""),"Thiếu vĩ độ / kinh độ mới",IF(OR(O68<12.5,O68>15,P68<107,P68>109.6),"Toạ độ ngoài Gia Lai (đảo vĩ/kinh độ?)",IF(Q68="","Chọn cách xác định",IF(U68>20000,"Dời hơn 20 km – kiểm tra lại","OK")))),IF(AND(N68<>"Sửa vị trí",OR(O68<>"",P68<>"")),"Có toạ độ mới nhưng kết quả không phải Sửa vị trí","OK")))
... A99: 95 | B99: eab23b7b-38f1-544f-44c1-0e13cb1faa64 | C99: Trung bình | D99: Trạm sạc Vinfast | E99: Trạm sạc | F99: OpenStreetMap | G99: Phường Pleiku, Gia Lai | H99: Phường Pleiku | I99: 13.978438 | J99: 108.01227 | K99: Đã đối chiếu | M99: Bản đồ | U99: =IF(AND(ISNUMBER(O99),ISNUMBER(P99)),ROUND(SQRT(((P99-J99)*111320*COS(RADIANS(I99)))^2+((O99-I99)*110540)^2),0),"") | V99: =IF(N99="","",IF(N99="Sửa vị trí",IF(OR(O99="",P99=""),"Thiếu vĩ độ / kinh độ mới",IF(OR(O99<12.5,O99>15,P99<107,P99>109.6),"Toạ độ ngoài Gia Lai (đảo vĩ/kinh độ?)",IF(Q99="","Chọn cách xác định",IF(U99>20000,"Dời hơn 20 km – kiểm tra lại","OK")))),IF(AND(N99<>"Sửa vị trí",OR(O99<>"",P99<>"")),"Có toạ độ mới nhưng kết quả không phải Sửa vị trí","OK")))
A100: 96 | B100: 0651565e-8665-4292-91e2-27d822dc1c22 | C100: Trung bình | D100: Quảng trường Đại Đoàn Kết | E100: Địa danh văn hóa | F100: Dữ liệu gialai-travel | G100: Đường Trần Hưng Đạo, phường Tây Sơn, TP. Pleiku, Gia Lai | H100: Phường Pleiku | I100: 13.982935 | J100: 108.00599 | K100: Đã hiệu chỉnh tự động | L100: Đã hiệu chỉnh theo OpenStreetMap (node/5997147685), dời 675 m | M100: Bản đồ | U100: =IF(AND(ISNUMBER(O100),ISNUMBER(P100)),ROUND(SQRT(((P100-J100)*111320*COS(RADIANS(I100)))^2+((O100-I100)*110540)^2),0),"") | V100: =IF(N100="","",IF(N100="Sửa vị trí",IF(OR(O100="",P100=""),"Thiếu vĩ độ / kinh độ mới",IF(OR(O100<12.5,O100>15,P100<107,P100>109.6),"Toạ độ ngoài Gia Lai (đảo vĩ/kinh độ?)",IF(Q100="","Chọn cách xác định",IF(U100>20000,"Dời hơn 20 km – kiểm tra lại","OK")))),IF(AND(N100<>"Sửa vị trí",OR(O100<>"",P100<>"")),"Có toạ độ mới nhưng kết quả không phải Sửa vị trí","OK")))
A101: 97 | B101: 30a07bf1-5376-52af-c2f0-027e6e4e59bc | C101: Thấp | D101: ATM 160 Hai Ba Trung, Phuong Dien Hong, Tinh Gia Lai (Agribank) | E101: ATM | F101: Website Agribank | G101: 160 Hai Ba Trung, Phuong Dien Hong, Tinh Gia Lai, Phường Diên Hồng, Gia Lai | H101: Phường Diên Hồng | I101: 13.979667 | J101: 107.99303 | K101: Đã đối chiếu | M101: Bản đồ | U101: =IF(AND(ISNUMBER(O101),ISNUMBER(P101)),ROUND(SQRT(((P101-J101)*111320*COS(RADIANS(I101)))^2+((O101-I101)*110540)^2),0),"") | V101: =IF(N101="","",IF(N101="Sửa vị trí",IF(OR(O101="",P101=""),"Thiếu vĩ độ / kinh độ mới",IF(OR(O101<12.5,O101>15,P101<107,P101>109.6),"Toạ độ ngoài Gia Lai (đảo vĩ/kinh độ?)",IF(Q101="","Chọn cách xác định",IF(U101>20000,"Dời hơn 20 km – kiểm tra lại","OK")))),IF(AND(N101<>"Sửa vị trí",OR(O101<>"",P101<>"")),"Có toạ độ mới nhưng kết quả không phải Sửa vị trí","OK")))
A102: 98 | B102: 190ceba4-53aa-f872-2676-9f75e615689f | C102: Thấp | D102: ATM 160 Hai Ba Trung, Phuong Dien Hong, Tinh Gia Lai (Agribank) | E102: ATM | F102: Website Agribank | G102: 160 Hai Ba Trung, Phuong Dien Hong, Tinh Gia Lai, Phường Diên Hồng, Gia Lai | H102: Phường Diên Hồng | I102: 13.979667 | J102: 107.99303 | K102: Đã đối chiếu | M102: Bản đồ | U102: =IF(AND(ISNUMBER(O102),ISNUMBER(P102)),ROUND(SQRT(((P102-J102)*111320*COS(RADIANS(I102)))^2+((O102-I102)*110540)^2),0),"") | V102: =IF(N102="","",IF(N102="Sửa vị trí",IF(OR(O102="",P102=""),"Thiếu vĩ độ / kinh độ mới",IF(OR(O102<12.5,O102>15,P102<107,P102>109.6),"Toạ độ ngoài Gia Lai (đảo vĩ/kinh độ?)",IF(Q102="","Chọn cách xác định",IF(U102>20000,"Dời hơn 20 km – kiểm tra lại","OK")))),IF(AND(N102<>"Sửa vị trí",OR(O102<>"",P102<>"")),"Có toạ độ mới nhưng kết quả không phải Sửa vị trí","OK")))
A103: 99 | B103: e94c55d9-01ec-e41b-1290-6ac00c13ce72 | C103: Thấp | D103: ATM 189 Tran Phu, Phuong Dien Hong, Tinh Gia Lai (Agribank) | E103: ATM | F103: Website Agribank | G103: 189 Tran Phu, Phuong Dien Hong, Tinh Gia Lai, Phường Diên Hồng, Gia Lai | H103: Phường Diên Hồng | I103: 13.977149 | J103: 107.99472 | K103: Đã đối chiếu | M103: Bản đồ | U103: =IF(AND(ISNUMBER(O103),ISNUMBER(P103)),ROUND(SQRT(((P103-J103)*111320*COS(RADIANS(I103)))^2+((O103-I103)*110540)^2),0),"") | V103: =IF(N103="","",IF(N103="Sửa vị trí",IF(OR(O103="",P103=""),"Thiếu vĩ độ / kinh độ mới",IF(OR(O103<12.5,O103>15,P103<107,P103>109.6),"Toạ độ ngoài Gia Lai (đảo vĩ/kinh độ?)",IF(Q103="","Chọn cách xác định",IF(U103>20000,"Dời hơn 20 km – kiểm tra lại","OK")))),IF(AND(N103<>"Sửa vị trí",OR(O103<>"",P103<>"")),"Có toạ độ mới nhưng kết quả không phải Sửa vị trí","OK")))
A104: 100 | B104: 53101530-358f-cbcb-5cd0-362196443733 | C104: Thấp | D104: ATM 25 Tang Bat Ho, Phuong Dien Hong, Tinh Gia Lai (Agribank) | E104: ATM | F104: Website Agribank | G104: 25 Tang Bat Ho, Phuong Dien Hong, Tinh Gia Lai, Phường Diên Hồng, Gia Lai | H104: Phường Diên Hồng | I104: 13.980355 | J104: 107.9955 | K104: Đã đối chiếu | M104: Bản đồ | U104: =IF(AND(ISNUMBER(O104),ISNUMBER(P104)),ROUND(SQRT(((P104-J104)*111320*COS(RADIANS(I104)))^2+((O104-I104)*110540)^2),0),"") | V104: =IF(N104="","",IF(N104="Sửa vị trí",IF(OR(O104="",P104=""),"Thiếu vĩ độ / kinh độ mới",IF(OR(O104<12.5,O104>15,P104<107,P104>109.6),"Toạ độ ngoài Gia Lai (đảo vĩ/kinh độ?)",IF(Q104="","Chọn cách xác định",IF(U104>20000,"Dời hơn 20 km – kiểm tra lại","OK")))),IF(AND(N104<>"Sửa vị trí",OR(O104<>"",P104<>"")),"Có toạ độ mới nhưng kết quả không phải Sửa vị trí","OK")))
A105: 101 | B105: ffbce83b-3812-b8b6-525c-2b7531a3091a | C105: Thấp | D105: ATM 25 Tang Bat Ho, Phuong Dien Hong, Tinh Gia Lai (Agribank) | E105: ATM | F105: Website Agribank | G105: 25 Tang Bat Ho, Phuong Dien Hong, Tinh Gia Lai, Phường Diên Hồng, Gia Lai | H105: Phường Diên Hồng | I105: 13.980355 | J105: 107.9955 | K105: Đã đối chiếu | M105: Bản đồ | U105: =IF(AND(ISNUMBER(O105),ISNUMBER(P105)),ROUND(SQRT(((P105-J105)*111320*COS(RADIANS(I105)))^2+((O105-I105)*110540)^2),0),"") | V105: =IF(N105="","",IF(N105="Sửa vị trí",IF(OR(O105="",P105=""),"Thiếu vĩ độ / kinh độ mới",IF(OR(O105<12.5,O105>15,P105<107,P105>109.6),"Toạ độ ngoài Gia Lai (đảo vĩ/kinh độ?)",IF(Q105="","Chọn cách xác định",IF(U105>20000,"Dời hơn 20 km – kiểm tra lại","OK")))),IF(AND(N105<>"Sửa vị trí",OR(O105<>"",P105<>"")),"Có toạ độ mới nhưng kết quả không phải Sửa vị trí","OK")))
A106: 102 | B106: eb41c788-d63a-a81c-3ca2-026a28113aad | C106: Thấp | D106: ATM 25 Tang Bat Ho, Phuong Dien Hong, Tinh Gia Lai (Agribank) | E106: ATM | F106: Website Agribank | G106: 25 Tang Bat Ho, Phuong Dien Hong, Tinh Gia Lai, Phường Diên Hồng, Gia Lai | H106: Phường Diên Hồng | I106: 13.980355 | J106: 107.9955 | K106: Đã đối chiếu | M106: Bản đồ | U106: =IF(AND(ISNUMBER(O106),ISNUMBER(P106)),ROUND(SQRT(((P106-J106)*111320*COS(RADIANS(I106)))^2+((O106-I106)*110540)^2),0),"") | V106: =IF(N106="","",IF(N106="Sửa vị trí",IF(OR(O106="",P106=""),"Thiếu vĩ độ / kinh độ mới",IF(OR(O106<12.5,O106>15,P106<107,P106>109.6),"Toạ độ ngoài Gia Lai (đảo vĩ/kinh độ?)",IF(Q106="","Chọn cách xác định",IF(U106>20000,"Dời hơn 20 km – kiểm tra lại","OK")))),IF(AND(N106<>"Sửa vị trí",OR(O106<>"",P106<>"")),"Có toạ độ mới nhưng kết quả không phải Sửa vị trí","OK")))
...

Sheet Tổng hợp
A1: TIẾN ĐỘ KIỂM TRA THEO DANH MỤC
A3: Danh mục | B3: Tổng | C3: Ưu tiên Cao | D3: Đã kiểm tra | E3: Vị trí đúng | F3: Sửa vị trí | G3: Không tồn tại / chuyển đi | H3: Dòng lỗi | I3: % đã kiểm tra
A4: ATM | B4: =COUNTIF('Danh sách kiểm tra'!$E$5:$E$152,A4) | C4: =COUNTIFS('Danh sách kiểm tra'!$E$5:$E$152,A4,'Danh sách kiểm tra'!$C$5:$C$152,"Cao") | D4: =COUNTIFS('Danh sách kiểm tra'!$E$5:$E$152,A4,'Danh sách kiểm tra'!$N$5:$N$152,"<>") | E4: =COUNTIFS('Danh sách kiểm tra'!$E$5:$E$152,A4,'Danh sách kiểm tra'!$N$5:$N$152,"Vị trí đúng") | F4: =COUNTIFS('Danh sách kiểm tra'!$E$5:$E$152,A4,'Danh sách kiểm tra'!$N$5:$N$152,"Sửa vị trí") | G4: =COUNTIFS('Danh sách kiểm tra'!$E$5:$E$152,A4,'Danh sách kiểm tra'!$N$5:$N$152,"Địa điểm không tồn tại")+COUNTIFS('Danh sách kiểm tra'!$E$5:$E$152,A4,'Danh sách kiểm tra'!$N$5:$N$152,"Đã chuyển đi (chưa rõ nơi mới)") | H4: =COUNTIFS('Danh sách kiểm tra'!$E$5:$E$152,A4,'Danh sách kiểm tra'!$V$5:$V$152,"<>OK",'Danh sách kiểm tra'!$N$5:$N$152,"<>") | I4: =IF(B4=0,0,D4/B4)
A5: Khách sạn | B5: =COUNTIF('Danh sách kiểm tra'!$E$5:$E$152,A5) | C5: =COUNTIFS('Danh sách kiểm tra'!$E$5:$E$152,A5,'Danh sách kiểm tra'!$C$5:$C$152,"Cao") | D5: =COUNTIFS('Danh sách kiểm tra'!$E$5:$E$152,A5,'Danh sách kiểm tra'!$N$5:$N$152,"<>") | E5: =COUNTIFS('Danh sách kiểm tra'!$E$5:$E$152,A5,'Danh sách kiểm tra'!$N$5:$N$152,"Vị trí đúng") | F5: =COUNTIFS('Danh sách kiểm tra'!$E$5:$E$152,A5,'Danh sách kiểm tra'!$N$5:$N$152,"Sửa vị trí") | G5: =COUNTIFS('Danh sách kiểm tra'!$E$5:$E$152,A5,'Danh sách kiểm tra'!$N$5:$N$152,"Địa điểm không tồn tại")+COUNTIFS('Danh sách kiểm tra'!$E$5:$E$152,A5,'Danh sách kiểm tra'!$N$5:$N$152,"Đã chuyển đi (chưa rõ nơi mới)") | H5: =COUNTIFS('Danh sách kiểm tra'!$E$5:$E$152,A5,'Danh sách kiểm tra'!$V$5:$V$152,"<>OK",'Danh sách kiểm tra'!$N$5:$N$152,"<>") | I5: =IF(B5=0,0,D5/B5)
A6: Cây xăng | B6: =COUNTIF('Danh sách kiểm tra'!$E$5:$E$152,A6) | C6: =COUNTIFS('Danh sách kiểm tra'!$E$5:$E$152,A6,'Danh sách kiểm tra'!$C$5:$C$152,"Cao") | D6: =COUNTIFS('Danh sách kiểm tra'!$E$5:$E$152,A6,'Danh sách kiểm tra'!$N$5:$N$152,"<>") | E6: =COUNTIFS('Danh sách kiểm tra'!$E$5:$E$152,A6,'Danh sách kiểm tra'!$N$5:$N$152,"Vị trí đúng") | F6: =COUNTIFS('Danh sách kiểm tra'!$E$5:$E$152,A6,'Danh sách kiểm tra'!$N$5:$N$152,"Sửa vị trí") | G6: =COUNTIFS('Danh sách kiểm tra'!$E$5:$E$152,A6,'Danh sách kiểm tra'!$N$5:$N$152,"Địa điểm không tồn tại")+COUNTIFS('Danh sách kiểm tra'!$E$5:$E$152,A6,'Danh sách kiểm tra'!$N$5:$N$152,"Đã chuyển đi (chưa rõ nơi mới)") | H6: =COUNTIFS('Danh sách kiểm tra'!$E$5:$E$152,A6,'Danh sách kiểm tra'!$V$5:$V$152,"<>OK",'Danh sách kiểm tra'!$N$5:$N$152,"<>") | I6: =IF(B6=0,0,D6/B6)
A7: Nhà nghỉ | B7: =COUNTIF('Danh sách kiểm tra'!$E$5:$E$152,A7) | C7: =COUNTIFS('Danh sách kiểm tra'!$E$5:$E$152,A7,'Danh sách kiểm tra'!$C$5:$C$152,"Cao") | D7: =COUNTIFS('Danh sách kiểm tra'!$E$5:$E$152,A7,'Danh sách kiểm tra'!$N$5:$N$152,"<>") | E7: =COUNTIFS('Danh sách kiểm tra'!$E$5:$E$152,A7,'Danh sách kiểm tra'!$N$5:$N$152,"Vị trí đúng") | F7: =COUNTIFS('Danh sách kiểm tra'!$E$5:$E$152,A7,'Danh sách kiểm tra'!$N$5:$N$152,"Sửa vị trí") | G7: =COUNTIFS('Danh sách kiểm tra'!$E$5:$E$152,A7,'Danh sách kiểm tra'!$N$5:$N$152,"Địa điểm không tồn tại")+COUNTIFS('Danh sách kiểm tra'!$E$5:$E$152,A7,'Danh sách kiểm tra'!$N$5:$N$152,"Đã chuyển đi (chưa rõ nơi mới)") | H7: =COUNTIFS('Danh sách kiểm tra'!$E$5:$E$152,A7,'Danh sách kiểm tra'!$V$5:$V$152,"<>OK",'Danh sách kiểm tra'!$N$5:$N$152,"<>") | I7: =IF(B7=0,0,D7/B7)
A8: Ngân hàng | B8: =COUNTIF('Danh sách kiểm tra'!$E$5:$E$152,A8) | C8: =COUNTIFS('Danh sách kiểm tra'!$E$5:$E$152,A8,'Danh sách kiểm tra'!$C$5:$C$152,"Cao") | D8: =COUNTIFS('Danh sách kiểm tra'!$E$5:$E$152,A8,'Danh sách kiểm tra'!$N$5:$N$152,"<>") | E8: =COUNTIFS('Danh sách kiểm tra'!$E$5:$E$152,A8,'Danh sách kiểm tra'!$N$5:$N$152,"Vị trí đúng") | F8: =COUNTIFS('Danh sách kiểm tra'!$E$5:$E$152,A8,'Danh sách kiểm tra'!$N$5:$N$152,"Sửa vị trí") | G8: =COUNTIFS('Danh sách kiểm tra'!$E$5:$E$152,A8,'Danh sách kiểm tra'!$N$5:$N$152,"Địa điểm không tồn tại")+COUNTIFS('Danh sách kiểm tra'!$E$5:$E$152,A8,'Danh sách kiểm tra'!$N$5:$N$152,"Đã chuyển đi (chưa rõ nơi mới)") | H8: =COUNTIFS('Danh sách kiểm tra'!$E$5:$E$152,A8,'Danh sách kiểm tra'!$V$5:$V$152,"<>OK",'Danh sách kiểm tra'!$N$5:$N$152,"<>") | I8: =IF(B8=0,0,D8/B8)
A9: Địa danh văn hóa | B9: =COUNTIF('Danh sách kiểm tra'!$E$5:$E$152,A9) | C9: =COUNTIFS('Danh sách kiểm tra'!$E$5:$E$152,A9,'Danh sách kiểm tra'!$C$5:$C$152,"Cao") | D9: =COUNTIFS('Danh sách kiểm tra'!$E$5:$E$152,A9,'Danh sách kiểm tra'!$N$5:$N$152,"<>") | E9: =COUNTIFS('Danh sách kiểm tra'!$E$5:$E$152,A9,'Danh sách kiểm tra'!$N$5:$N$152,"Vị trí đúng") | F9: =COUNTIFS('Danh sách kiểm tra'!$E$5:$E$152,A9,'Danh sách kiểm tra'!$N$5:$N$152,"Sửa vị trí") | G9: =COUNTIFS('Danh sách kiểm tra'!$E$5:$E$152,A9,'Danh sách kiểm tra'!$N$5:$N$152,"Địa điểm không tồn tại")+COUNTIFS('Danh sách kiểm tra'!$E$5:$E$152,A9,'Danh sách kiểm tra'!$N$5:$N$152,"Đã chuyển đi (chưa rõ nơi mới)") | H9: =COUNTIFS('Danh sách kiểm tra'!$E$5:$E$152,A9,'Danh sách kiểm tra'!$V$5:$V$152,"<>OK",'Danh sách kiểm tra'!$N$5:$N$152,"<>") | I9: =IF(B9=0,0,D9/B9)
A10: Chợ | B10: =COUNTIF('Danh sách kiểm tra'!$E$5:$E$152,A10) | C10: =COUNTIFS('Danh sách kiểm tra'!$E$5:$E$152,A10,'Danh sách kiểm tra'!$C$5:$C$152,"Cao") | D10: =COUNTIFS('Danh sách kiểm tra'!$E$5:$E$152,A10,'Danh sách kiểm tra'!$N$5:$N$152,"<>") | E10: =COUNTIFS('Danh sách kiểm tra'!$E$5:$E$152,A10,'Danh sách kiểm tra'!$N$5:$N$152,"Vị trí đúng") | F10: =COUNTIFS('Danh sách kiểm tra'!$E$5:$E$152,A10,'Danh sách kiểm tra'!$N$5:$N$152,"Sửa vị trí") | G10: =COUNTIFS('Danh sách kiểm tra'!$E$5:$E$152,A10,'Danh sách kiểm tra'!$N$5:$N$152,"Địa điểm không tồn tại")+COUNTIFS('Danh sách kiểm tra'!$E$5:$E$152,A10,'Danh sách kiểm tra'!$N$5:$N$152,"Đã chuyển đi (chưa rõ nơi mới)") | H10: =COUNTIFS('Danh sách kiểm tra'!$E$5:$E$152,A10,'Danh sách kiểm tra'!$V$5:$V$152,"<>OK",'Danh sách kiểm tra'!$N$5:$N$152,"<>") | I10: =IF(B10=0,0,D10/B10)
A11: Danh lam thắng cảnh | B11: =COUNTIF('Danh sách kiểm tra'!$E$5:$E$152,A11) | C11: =COUNTIFS('Danh sách kiểm tra'!$E$5:$E$152,A11,'Danh sách kiểm tra'!$C$5:$C$152,"Cao") | D11: =COUNTIFS('Danh sách kiểm tra'!$E$5:$E$152,A11,'Danh sách kiểm tra'!$N$5:$N$152,"<>") | E11: =COUNTIFS('Danh sách kiểm tra'!$E$5:$E$152,A11,'Danh sách kiểm tra'!$N$5:$N$152,"Vị trí đúng") | F11: =COUNTIFS('Danh sách kiểm tra'!$E$5:$E$152,A11,'Danh sách kiểm tra'!$N$5:$N$152,"Sửa vị trí") | G11: =COUNTIFS('Danh sách kiểm tra'!$E$5:$E$152,A11,'Danh sách kiểm tra'!$N$5:$N$152,"Địa điểm không tồn tại")+COUNTIFS('Danh sách kiểm tra'!$E$5:$E$152,A11,'Danh sách kiểm tra'!$N$5:$N$152,"Đã chuyển đi (chưa rõ nơi mới)") | H11: =COUNTIFS('Danh sách kiểm tra'!$E$5:$E$152,A11,'Danh sách kiểm tra'!$V$5:$V$152,"<>OK",'Danh sách kiểm tra'!$N$5:$N$152,"<>") | I11: =IF(B11=0,0,D11/B11)
A12: Homestay | B12: =COUNTIF('Danh sách kiểm tra'!$E$5:$E$152,A12) | C12: =COUNTIFS('Danh sách kiểm tra'!$E$5:$E$152,A12,'Danh sách kiểm tra'!$C$5:$C$152,"Cao") | D12: =COUNTIFS('Danh sách kiểm tra'!$E$5:$E$152,A12,'Danh sách kiểm tra'!$N$5:$N$152,"<>") | E12: =COUNTIFS('Danh sách kiểm tra'!$E$5:$E$152,A12,'Danh sách kiểm tra'!$N$5:$N$152,"Vị trí đúng") | F12: =COUNTIFS('Danh sách kiểm tra'!$E$5:$E$152,A12,'Danh sách kiểm tra'!$N$5:$N$152,"Sửa vị trí") | G12: =COUNTIFS('Danh sách kiểm tra'!$E$5:$E$152,A12,'Danh sách kiểm tra'!$N$5:$N$152,"Địa điểm không tồn tại")+COUNTIFS('Danh sách kiểm tra'!$E$5:$E$152,A12,'Danh sách kiểm tra'!$N$5:$N$152,"Đã chuyển đi (chưa rõ nơi mới)") | H12: =COUNTIFS('Danh sách kiểm tra'!$E$5:$E$152,A12,'Danh sách kiểm tra'!$V$5:$V$152,"<>OK",'Danh sách kiểm tra'!$N$5:$N$152,"<>") | I12: =IF(B12=0,0,D12/B12)
A13: Địa điểm check-in | B13: =COUNTIF('Danh sách kiểm tra'!$E$5:$E$152,A13) | C13: =COUNTIFS('Danh sách kiểm tra'!$E$5:$E$152,A13,'Danh sách kiểm tra'!$C$5:$C$152,"Cao") | D13: =COUNTIFS('Danh sách kiểm tra'!$E$5:$E$152,A13,'Danh sách kiểm tra'!$N$5:$N$152,"<>") | E13: =COUNTIFS('Danh sách kiểm tra'!$E$5:$E$152,A13,'Danh sách kiểm tra'!$N$5:$N$152,"Vị trí đúng") | F13: =COUNTIFS('Danh sách kiểm tra'!$E$5:$E$152,A13,'Danh sách kiểm tra'!$N$5:$N$152,"Sửa vị trí") | G13: =COUNTIFS('Danh sách kiểm tra'!$E$5:$E$152,A13,'Danh sách kiểm tra'!$N$5:$N$152,"Địa điểm không tồn tại")+COUNTIFS('Danh sách kiểm tra'!$E$5:$E$152,A13,'Danh sách kiểm tra'!$N$5:$N$152,"Đã chuyển đi (chưa rõ nơi mới)") | H13: =COUNTIFS('Danh sách kiểm tra'!$E$5:$E$152,A13,'Danh sách kiểm tra'!$V$5:$V$152,"<>OK",'Danh sách kiểm tra'!$N$5:$N$152,"<>") | I13: =IF(B13=0,0,D13/B13)
A14: Trạm sạc | B14: =COUNTIF('Danh sách kiểm tra'!$E$5:$E$152,A14) | C14: =COUNTIFS('Danh sách kiểm tra'!$E$5:$E$152,A14,'Danh sách kiểm tra'!$C$5:$C$152,"Cao") | D14: =COUNTIFS('Danh sách kiểm tra'!$E$5:$E$152,A14,'Danh sách kiểm tra'!$N$5:$N$152,"<>") | E14: =COUNTIFS('Danh sách kiểm tra'!$E$5:$E$152,A14,'Danh sách kiểm tra'!$N$5:$N$152,"Vị trí đúng") | F14: =COUNTIFS('Danh sách kiểm tra'!$E$5:$E$152,A14,'Danh sách kiểm tra'!$N$5:$N$152,"Sửa vị trí") | G14: =COUNTIFS('Danh sách kiểm tra'!$E$5:$E$152,A14,'Danh sách kiểm tra'!$N$5:$N$152,"Địa điểm không tồn tại")+COUNTIFS('Danh sách kiểm tra'!$E$5:$E$152,A14,'Danh sách kiểm tra'!$N$5:$N$152,"Đã chuyển đi (chưa rõ nơi mới)") | H14: =COUNTIFS('Danh sách kiểm tra'!$E$5:$E$152,A14,'Danh sách kiểm tra'!$V$5:$V$152,"<>OK",'Danh sách kiểm tra'!$N$5:$N$152,"<>") | I14: =IF(B14=0,0,D14/B14)
A15: Tổng | B15: =SUM(B4:B14) | C15: =SUM(C4:C14) | D15: =SUM(D4:D14) | E15: =SUM(E4:E14) | F15: =SUM(F4:F14) | G15: =SUM(G4:G14) | H15: =SUM(H4:H14) | I15: =IF(B15=0,0,D15/B15)
