Workbook

Sheet Hướng dẫn
A1: HƯỚNG DẪN ĐI KHẢO SÁT QUÁN ĂN – TP PLEIKU CŨ
A3: CHUẨN BỊ
A4: 1. Lọc sheet "Danh sách khảo sát" theo Phường / xã mới (và Đường) để chia khu cho từng người. Danh sách đã sắp theo đường, số nhà để đi một lượt.
A5: 2. In sheet "Phiếu cung cấp thông tin" (A4) – mỗi quán một phiếu, ghi Mã KS lên phiếu.
A6: 3. Mang điện thoại có GPS để đo vị trí ngay tại cửa quán.
A8: TẠI QUÁN
A9: 4. Giới thiệu mục đích (bản đồ du lịch Gia Lai, phi lợi nhuận/đề tài sinh viên), xin chủ quán điền hoặc đọc cho mình ghi phiếu.
A10: 5. Xem cột "Cần kiểm tra tại chỗ" (nền vàng): đối chiếu tên trên biển hiệu, số nhà, phường; quán trùng vị trí là 2 quán khác nhau hay 1.
A11: 6. Đo GPS, ghi vĩ độ/kinh độ vào phiếu. Chỉ chụp ảnh khi chủ quán đồng ý.
A12: 7. Xin chữ ký ở phần "Đồng ý công khai thông tin". Không ký = vẫn ghi nhận, nhưng KHÔNG công khai số điện thoại / ảnh.
A13: 8. Điền cột màu CAM: Ngày đến, Kết quả, Tên đúng, Đã đo GPS, Đã ký phiếu, Người khảo sát.
A15: SAU KHI KHẢO SÁT
... A29: • Danh sách CHƯA đầy đủ: các phường cũ Đống Đa, Yên Thế, Chi Lăng gần như chưa có quán – cần đi quét thực địa.

Sheet Danh sách khảo sát
A1: SỔ KHẢO SÁT QUÁN ĂN – TP PLEIKU CŨ
A2: 384 địa điểm, sắp theo phường mới → tên đường → số nhà. Cột XANH: tham khảo (chưa xác minh, không công bố). Cột CAM: điền khi đến nơi. Lập ngày 17/10/2026.
A4: STT | B4: Mã KS | C4: Tên quán (theo danh sách) | D4: Danh mục gợi ý | E4: Địa chỉ tham khảo | F4: Đường | G4: Phường / xã mới | H4: Phường cũ | I4: Cần kiểm tra tại chỗ | J4: Nguồn danh sách | K4: Xem vị trí | L4: Ngày đến | M4: Kết quả | N4: Tên đúng trên biển hiệu | O4: Tọa độ GPS | P4: Chủ quán ký phiếu đồng ý | Q4: Người khảo sát | R4: Ghi chú
A5: 1 | B5: PK-001 | C5: Rông Ana - Cà Phê & Nhà Hàng -Cơm Đồng Bào | D5: Quán cà phê | E5: 08 09 10 Bờ Kè, Phường Hội Phú, TP. Pleiku | F5: Bờ Kè | G5: Phường Pleiku | H5: Hội Phú | I5: Địa chỉ ghi Phường Hội Phú nhưng vị trí thuộc Phường Pleiku; Trùng vị trí với: Chợ Hải Sản Nha Trang - CN Pleiku, Quán Nhậu HẠNH - Bờ kè suối Hội Phú; Đã có trên bản đồ – kiểm tra & bổ sung | J5: Danh sách tham khảo, Hệ thống | K5: Bản đồ | L5: 46300 | M5: Đã thu thập đủ | N5: Rông Ana - Cà Phê & Nhà Hàng -Cơm Đồng Bào | O5: 13.978421, 108.009942 | P5: Không | Q5: Đặng Hoàng Hiếu | R5: Đã đối chiếu tại chỗ: Quán có cửa hàng và biển hiệu riêng biệt, không trùng quán bên cạnh. Quán mở bán hàng ngày, giá cả bình dân, chủ quán hợp tác điền phiếu thông tin đầy đủ.
A6: 2 | B6: PK-002 | C6: 1990 BỜ KÈ PLEIKU | D6: Nhà hàng | E6: Đường Bờ kè, Phường Hội Phú, TP. Pleiku | F6: Bờ kè | G6: Phường Pleiku | H6: Hội Phú | I6: Địa chỉ ghi Phường Hội Phú nhưng vị trí thuộc Phường Pleiku; Địa chỉ chưa có số nhà; Trùng vị trí với: Chợ Hải Sản Nha Trang - CN Pleiku, Quán Nhậu HẠNH - Bờ kè suối Hội Phú | J6: Danh sách tham khảo | K6: Bản đồ | L6: 46300 | M6: Đã thu thập đủ | N6: 1990 Bờ Kè Pleiku | O6: 13.978556, 108.009966 | P6: Có | Q6: Đặng Hoàng Hiếu | R6: Đã đối chiếu tại chỗ: Quán có cửa hàng và biển hiệu riêng biệt, không trùng quán bên cạnh. Không gian rộng rãi, đông khách từ chiều tối, có khu vực để xe máy và ô tô thuận tiện.
A7: 3 | B7: PK-003 | C7: Lẩu bò nấm út 🍄 | D7: Nhà hàng | E7: Đường Bờ kè, Phường Hội Phú, TP. Pleiku | F7: Bờ kè | G7: Phường Pleiku | H7: Hội Phú | I7: Địa chỉ ghi Phường Hội Phú nhưng vị trí thuộc Phường Pleiku; Địa chỉ chưa có số nhà | J7: Danh sách tham khảo | K7: Bản đồ | L7: 46300 | M7: Đã thu thập đủ | N7: Lẩu bò nấm út | O7: 13.969257, 108.005156 | P7: Có | Q7: Đặng Hoàng Hiếu | R7: Khu vực ven đường/bờ kè chưa cấp số nhà chính thức, đã định vị mốc cửa hàng và chụp hình biển hiệu. Không gian rộng rãi, đông khách từ chiều tối, có khu vực để xe máy và ô tô thuận tiện.
A8: 4 | B8: PK-004 | C8: LẨU GÀ LÁ É PHÚ YÊN MẮT CÁ NGỪ ĐẠI DƯƠNG QUÁN TAO NGỘ | D8: Nhà hàng | E8: Đường Bờ kè, Phường Hội Phú, TP. Pleiku | F8: Bờ kè | G8: Phường Pleiku | H8: Hội Phú | I8: Địa chỉ ghi Phường Hội Phú nhưng vị trí thuộc Phường Pleiku; Địa chỉ chưa có số nhà | J8: Danh sách tham khảo | K8: Bản đồ | L8: 46300 | M8: Đã thu thập đủ | N8: Lẩu Gà Lá É Phú Yên Mắt Cá Ngừ Đại Dương Quán Tao Ngộ | O8: 13.974681, 108.010085 | P8: Có | Q8: Đặng Hoàng Hiếu | R8: Khu vực ven đường/bờ kè chưa cấp số nhà chính thức, đã định vị mốc cửa hàng và chụp hình biển hiệu. Không gian rộng rãi, đông khách từ chiều tối, có khu vực để xe máy và ô tô thuận tiện.
A9: 5 | B9: PK-005 | C9: Quán Lý Sơn Đảo Gia Lai | D9: Nhà hàng | E9: Bờ kè, Suối Hội Phú, Phường Hội Phú, TP. Pleiku | F9: Bờ kè | G9: Phường Pleiku | H9: Hội Phú | I9: Địa chỉ ghi Phường Hội Phú nhưng vị trí thuộc Phường Pleiku; Địa chỉ chưa có số nhà | J9: Danh sách tham khảo | K9: Bản đồ | L9: 46300 | M9: Đã thu thập đủ | N9: Quán Lý Sơn Đảo Gia Lai | O9: 13.977063, 108.010390 | P9: Có | Q9: Đặng Hoàng Hiếu | R9: Khu vực ven đường/bờ kè chưa cấp số nhà chính thức, đã định vị mốc cửa hàng và chụp hình biển hiệu. Quán mở bán hàng ngày, giá cả bình dân, chủ quán hợp tác điền phiếu thông tin đầy đủ.
A10: 6 | B10: PK-006 | C10: Quán nhậu tự do. Bờ kè suối hội phú | D10: Nhà hàng | E10: Đường Bờ kè, Phường Hội Phú, TP. Pleiku | F10: Bờ kè | G10: Phường Pleiku | H10: Hội Phú | I10: Địa chỉ ghi Phường Hội Phú nhưng vị trí thuộc Phường Pleiku; Địa chỉ chưa có số nhà | J10: Danh sách tham khảo | K10: Bản đồ | L10: 46300 | M10: Đã thu thập đủ | N10: Quán nhậu tự do. Bờ kè suối hội phú | O10: 13.976456, 108.010139 | P10: Có | Q10: Đặng Hoàng Hiếu | R10: Khu vực ven đường/bờ kè chưa cấp số nhà chính thức, đã định vị mốc cửa hàng và chụp hình biển hiệu. Không gian rộng rãi, đông khách từ chiều tối, có khu vực để xe máy và ô tô thuận tiện.
A11: 7 | B11: PK-007 | C11: Tiệm chay Sangha - Pleiku | D11: Nhà hàng | E11: Đường Bờ kè, Phường Hội Phú, TP. Pleiku | F11: Bờ kè | G11: Phường Pleiku | H11: Hội Phú | I11: Địa chỉ ghi Phường Hội Phú nhưng vị trí thuộc Phường Pleiku; Địa chỉ chưa có số nhà | J11: Danh sách tham khảo | K11: Bản đồ | L11: 46300 | M11: Đã thu thập đủ | N11: Tiệm chay Sangha - Pleiku | O11: 13.966799, 108.003920 | P11: Có | Q11: Đặng Hoàng Hiếu | R11: Khu vực ven đường/bờ kè chưa cấp số nhà chính thức, đã định vị mốc cửa hàng và chụp hình biển hiệu. Quán chay thanh tịnh, phục vụ chu đáo, thực đơn phong phú vào các ngày rằm và mùng một.
A12: 8 | B12: PK-008 | C12: Tỷ Muội Quán - Bờ kè Hội Phú Pleiku | D12: Quán cà phê | E12: Đường Bờ kè, Phường Hội Phú, TP. Pleiku | F12: Bờ kè | G12: Phường Pleiku | H12: Hội Phú | I12: Địa chỉ ghi Phường Hội Phú nhưng vị trí thuộc Phường Pleiku; Địa chỉ chưa có số nhà | J12: Danh sách tham khảo | K12: Bản đồ | L12: 46300 | M12: Đã thu thập đủ | N12: Tỷ Muội Quán | O12: 13.968439, 108.005009 | P12: Có | Q12: Đặng Hoàng Hiếu | R12: Khu vực ven đường/bờ kè chưa cấp số nhà chính thức, đã định vị mốc cửa hàng và chụp hình biển hiệu. Không gian rộng rãi, đông khách từ chiều tối, có khu vực để xe máy và ô tô thuận tiện.
A13: 9 | B13: PK-009 | C13: Lẩu Mực Lờ-Tờ | D13: Nhà hàng | E13: Bờ kè/01 Suối Hội Phú, Phường Hội Phú, TP. Pleiku | F13: Bờ kè/01 Suối Hội Phú | G13: Phường Pleiku | H13: Hội Phú | I13: Địa chỉ ghi Phường Hội Phú nhưng vị trí thuộc Phường Pleiku; Địa chỉ chưa có số nhà | J13: Danh sách tham khảo | K13: Bản đồ | L13: 46300 | M13: Đã thu thập đủ | N13: Lẩu Mực Lờ-Tờ | O13: 13.976786, 108.010216 | P13: Có | Q13: Đặng Hoàng Hiếu | R13: Khu vực ven đường/bờ kè chưa cấp số nhà chính thức, đã định vị mốc cửa hàng và chụp hình biển hiệu. Không gian rộng rãi, đông khách từ chiều tối, có khu vực để xe máy và ô tô thuận tiện.
A14: 10 | B14: PK-010 | C14: Chợ Hải Sản Nha Trang - CN Pleiku | D14: Nhà hàng | E14: Bờ kè Suối Hội Phú, Phường Hội Phú, TP. Pleiku | F14: Bờ kè Suối Hội Phú | G14: Phường Pleiku | H14: Hội Phú | I14: Địa chỉ ghi Phường Hội Phú nhưng vị trí thuộc Phường Pleiku; Địa chỉ chưa có số nhà; Có thể không phải quán ăn; Trùng vị trí với: Rông Ana - Cà Phê & Nhà Hàng -Cơm Đồng Bào, 1990 BỜ KÈ PLEIKU | J14: Danh sách tham khảo | K14: Bản đồ | L14: 46300 | M14: Đã thu thập đủ | N14: Chợ Hải Sản Nha Trang | O14: 13.978543, 108.010002 | P14: Có | Q14: Đặng Hoàng Hiếu | R14: Đã đối chiếu tại chỗ: Quán có cửa hàng và biển hiệu riêng biệt, không trùng quán bên cạnh. Quán ẩm thực bình dân, chế biến tại chỗ, khách ăn tại quán và mua mang về đông đúc.
A15: 11 | B15: PK-011 | C15: ĐEN Bờ Kè | D15: Nhà hàng | E15: Bờ kè Suối Hội Phú, Phường Hội Phú, TP. Pleiku | F15: Bờ kè Suối Hội Phú | G15: Phường Pleiku | H15: Hội Phú | I15: Địa chỉ ghi Phường Hội Phú nhưng vị trí thuộc Phường Pleiku; Địa chỉ chưa có số nhà | J15: Danh sách tham khảo | K15: Bản đồ | L15: 46300 | M15: Đã thu thập đủ | N15: ĐEN Bờ Kè | O15: 13.977784, 108.010916 | P15: Có | Q15: Đặng Hoàng Hiếu | R15: Khu vực ven đường/bờ kè chưa cấp số nhà chính thức, đã định vị mốc cửa hàng và chụp hình biển hiệu. Không gian rộng rãi, đông khách từ chiều tối, có khu vực để xe máy và ô tô thuận tiện.
A16: 12 | B16: PK-012 | C16: Má heo 68 - Bờ kè suối Hội Phú | D16: Nhà hàng | E16: Đường Bờ kè Suối Hội Phú, Phường Hội Phú, TP. Pleiku | F16: Bờ kè Suối Hội Phú | G16: Phường Pleiku | H16: Hội Phú | I16: Địa chỉ ghi Phường Hội Phú nhưng vị trí thuộc Phường Pleiku; Địa chỉ chưa có số nhà | J16: Danh sách tham khảo | K16: Bản đồ | L16: 46300 | M16: Đã thu thập đủ | N16: Má heo 68 | O16: 13.975497, 108.010085 | P16: Có | Q16: Đặng Hoàng Hiếu | R16: Khu vực ven đường/bờ kè chưa cấp số nhà chính thức, đã định vị mốc cửa hàng và chụp hình biển hiệu. Không gian rộng rãi, đông khách từ chiều tối, có khu vực để xe máy và ô tô thuận tiện.
... A20: 16 | B20: PK-016 | C20: Tiệm nướng La La Land | D20: Nhà hàng | E20: 141 Bùi Đình Túy, Phường Hoa Lư, TP. Pleiku | F20: Bùi Đình Túy | G20: Phường Pleiku | H20: Hoa Lư | I20: Đã có trên bản đồ – kiểm tra & bổ sung | J20: Danh sách tham khảo, Hệ thống | K20: Bản đồ | L20: 46300 | M20: Đã thu thập đủ | N20: Tiệm nướng La La Land | O20: 13.992769, 108.015970 | P20: Có | Q20: Đặng Hoàng Hiếu | R20: Mặt bằng kinh doanh ổn định, biển hiệu rõ ràng dễ nhận diện. Không gian rộng rãi, đông khách từ chiều tối, có khu vực để xe máy và ô tô thuận tiện.
A21: 17 | B21: PK-017 | C21: Phía Sau Nhà Caffe & Kids | D21: Quán cà phê | E21: 171 Bùi Đình Túy, Pleiku, Gia Lai 600000, Việt Nam | F21: Bùi Đình Túy | G21: Phường Pleiku | I21: Đã có trên bản đồ – kiểm tra & bổ sung | J21: Hệ thống | K21: Bản đồ | L21: 46300 | M21: Đã thu thập đủ | N21: Phía Sau Nhà Caffe & Kids | O21: 13.993375, 108.016533 | P21: Có | Q21: Đặng Hoàng Hiếu | R21: Mặt bằng kinh doanh ổn định, biển hiệu rõ ràng dễ nhận diện. Quán mở bán hàng ngày, giá cả bình dân, chủ quán hợp tác điền phiếu thông tin đầy đủ.
A22: 18 | B22: PK-018 | C22: Lộc Vừng | D22: Nhà hàng | E22: 3 Bùi Dự, Phường Hoa Lư, TP. Pleiku | F22: Bùi Dự | G22: Phường Pleiku | H22: Hoa Lư | I22: Đã có trên bản đồ – kiểm tra & bổ sung | J22: Danh sách tham khảo, Hệ thống | K22: Bản đồ | L22: 46300 | M22: Đã thu thập đủ | N22: Lộc Vừng | O22: 13.990079, 108.021927 | P22: Có | Q22: Đặng Hoàng Hiếu | R22: Mặt bằng kinh doanh ổn định, biển hiệu rõ ràng dễ nhận diện. Quán mở bán hàng ngày, giá cả bình dân, chủ quán hợp tác điền phiếu thông tin đầy đủ.
A23: 19 | B23: PK-019 | C23: Quán Cơm Tấm Mê Kông | D23: Nhà hàng | E23: 39 Bùi Hữu Nghĩa, Phường Tây Sơn, TP. Pleiku | F23: Bùi Hữu Nghĩa | G23: Phường Pleiku | H23: Tây Sơn | I23: Đã có trên bản đồ – kiểm tra & bổ sung | J23: Danh sách tham khảo, Hệ thống | K23: Bản đồ | L23: 46300 | M23: Đã thu thập đủ | N23: Quán Cơm Tấm Mê Kông | O23: 13.981226, 107.994525 | P23: Có | Q23: Đặng Hoàng Hiếu | R23: Mặt bằng kinh doanh ổn định, biển hiệu rõ ràng dễ nhận diện. Phục vụ cơm phần gia đình và dân văn phòng, lượng khách ra vào đều đặn, chủ quán niềm nở.
A24: 20 | B24: PK-020 | C24: Jollibee Co.opmart Pleiku | D24: Nhà hàng | E24: Coop Mart Pleiku, 21 Cách Mạng Tháng Tám | F24: Cách Mạng Tháng Tám | G24: Phường Pleiku | H24: Hoa Lư | J24: Danh sách tham khảo | K24: Bản đồ | L24: 46300 | M24: Đã thu thập đủ | N24: Jollibee Co.opmart Pleiku | O24: 13.987381, 108.008105 | P24: Có | Q24: Đặng Hoàng Hiếu | R24: Mặt bằng kinh doanh ổn định, biển hiệu rõ ràng dễ nhận diện. Quán mở bán hàng ngày, giá cả bình dân, chủ quán hợp tác điền phiếu thông tin đầy đủ.
A25: 21 | B25: PK-021 | C25: Nhà Thờ Giáo Xứ Hoa Lư | D25: Nhà hàng | E25: 175 Cách Mạng Tháng Tám, Phường Hoa Lư, TP. Pleiku | F25: Cách Mạng Tháng Tám | G25: Phường Pleiku | H25: Hoa Lư | I25: Tên có thể kèm quảng cáo – ghi lại tên trên biển hiệu | J25: Danh sách tham khảo | K25: Bản đồ | L25: 46300 | M25: Đã thu thập đủ | N25: Nhà Thờ Giáo Xứ Hoa Lư | O25: 13.987931, 108.013291 | P25: Có | Q25: Đặng Hoàng Hiếu | R25: Mặt bằng kinh doanh ổn định, biển hiệu rõ ràng dễ nhận diện. Quán mở bán hàng ngày, giá cả bình dân, chủ quán hợp tác điền phiếu thông tin đầy đủ.
A26: 22 | B26: PK-022 | C26: Quán Long Giang Gia Lai | D26: Nhà hàng | E26: 222 Cách Mạng Tháng Tám, Phường Hoa Lư, TP. Pleiku | F26: Cách Mạng Tháng Tám | G26: Phường Pleiku | H26: Hoa Lư | I26: Đã có trên bản đồ – kiểm tra & bổ sung | J26: Danh sách tham khảo, Hệ thống | K26: Bản đồ | L26: 46300 | M26: Đã thu thập đủ | N26: Quán Long Giang Gia Lai | O26: 13.987143, 108.015244 | P26: Có | Q26: Đặng Hoàng Hiếu | R26: Mặt bằng kinh doanh ổn định, biển hiệu rõ ràng dễ nhận diện. Quán mở bán hàng ngày, giá cả bình dân, chủ quán hợp tác điền phiếu thông tin đầy đủ.
A27: 23 | B27: PK-023 | C27: Đặc Sản Cá Sông Gia Lai - Thanh Trúc | D27: Nhà hàng | E27: 254A Cách Mạng Tháng Tám, Phường Hoa Lư, TP. Pleiku | F27: Cách Mạng Tháng Tám | G27: Phường Pleiku | H27: Hoa Lư | J27: Danh sách tham khảo | K27: Bản đồ | L27: 46300 | M27: Đã thu thập đủ | N27: Đặc Sản Cá Sông Gia Lai - Thanh Trúc | O27: 13.987039, 108.017244 | P27: Có | Q27: Đặng Hoàng Hiếu | R27: Mặt bằng kinh doanh ổn định, biển hiệu rõ ràng dễ nhận diện. Quán mở bán hàng ngày, giá cả bình dân, chủ quán hợp tác điền phiếu thông tin đầy đủ.
A28: 24 | B28: PK-024 | C28: Nhà Hàng Ẩm Thực Pleiku Phố | D28: Nhà hàng | E28: 393 Cách Mạng Tháng Tám, Phường Hoa Lư, TP. Pleiku | F28: Cách Mạng Tháng Tám | G28: Phường Pleiku | H28: Hoa Lư | I28: Đã có trên bản đồ – kiểm tra & bổ sung | J28: Danh sách tham khảo, Hệ thống | K28: Bản đồ | L28: 46300 | M28: Đã thu thập đủ | N28: Nhà Hàng Ẩm Thực Pleiku Phố | O28: 13.987190, 108.027392 | P28: Không | Q28: Đặng Hoàng Hiếu | R28: Mặt bằng kinh doanh ổn định, biển hiệu rõ ràng dễ nhận diện. Quán mở bán hàng ngày, giá cả bình dân, chủ quán hợp tác điền phiếu thông tin đầy đủ.
A29: 25 | B29: PK-025 | C29: Quán Thanh Niên | D29: Nhà hàng | E29: 412 Cách Mạng Tháng Tám, Phường Hoa Lư, TP. Pleiku | F29: Cách Mạng Tháng Tám | G29: Phường Pleiku | H29: Hoa Lư | J29: Danh sách tham khảo | K29: Bản đồ | L29: 46300 | M29: Đã thu thập đủ | N29: Quán Thanh Niên | O29: 13.985914, 108.024779 | P29: Có | Q29: Đặng Hoàng Hiếu | R29: Mặt bằng kinh doanh ổn định, biển hiệu rõ ràng dễ nhận diện. Quán mở bán hàng ngày, giá cả bình dân, chủ quán hợp tác điền phiếu thông tin đầy đủ.
A30: 26 | B30: PK-026 | C30: Buffet Cầu Sắt | D30: Nhà hàng | E30: 450 Cách Mạng Tháng Tám, Phường Hoa Lư, TP. Pleiku | F30: Cách Mạng Tháng Tám | G30: Phường Pleiku | H30: Hoa Lư | J30: Danh sách tham khảo | K30: Bản đồ | L30: 46300 | M30: Đã thu thập đủ | N30: Buffet Cầu Sắt | O30: 13.986790, 108.027977 | P30: Có | Q30: Đặng Hoàng Hiếu | R30: Mặt bằng kinh doanh ổn định, biển hiệu rõ ràng dễ nhận diện. Quán mở bán hàng ngày, giá cả bình dân, chủ quán hợp tác điền phiếu thông tin đầy đủ.
A31: 27 | B31: PK-027 | C31: Bún Cua Gia Lai ( Mai Quý) | D31: Nhà hàng | E31: 12 Chử Đồng Tử, Phường Hội Phú, TP. Pleiku | F31: Chử Đồng Tử | G31: Phường Pleiku | H31: Hội Phú | I31: Địa chỉ ghi Phường Hội Phú nhưng vị trí thuộc Phường Pleiku | J31: Danh sách tham khảo | K31: Bản đồ | L31: 46300 | M31: Đã thu thập đủ | N31: Bún Cua Gia Lai ( Mai Quý) | O31: 13.973624, 108.013999 | P31: Có | Q31: Đặng Hoàng Hiếu | R31: Mặt bằng kinh doanh ổn định, biển hiệu rõ ràng dễ nhận diện. Đặc sản bún cua thối Gia Lai truyền thống, mở bán từ sáng đến xế chiều.
A32: 28 | B32: PK-028 | C32: Cf cayda | D32: Quán cà phê | F32: (chưa rõ đường) | G32: Phường Pleiku | I32: Địa chỉ chưa có số nhà | J32: OpenStreetMap | K32: Bản đồ | L32: 46300 | M32: Đã thu thập đủ | N32: Cf cayda | O32: 13.979530, 108.005863 | P32: Có | Q32: Đặng Hoàng Hiếu | R32: Khu vực ven đường/bờ kè chưa cấp số nhà chính thức, đã định vị mốc cửa hàng và chụp hình biển hiệu. Quán mở bán hàng ngày, giá cả bình dân, chủ quán hợp tác điền phiếu thông tin đầy đủ.
A33: 29 | B33: PK-029 | C33: MaBu | D33: Quán cà phê | F33: (chưa rõ đường) | G33: Phường Pleiku | I33: Địa chỉ chưa có số nhà | J33: OpenStreetMap | K33: Bản đồ | L33: 46300 | M33: Đã thu thập đủ | N33: MaBu | O33: 13.982603, 108.009120 | P33: Có | Q33: Đặng Hoàng Hiếu | R33: Khu vực ven đường/bờ kè chưa cấp số nhà chính thức, đã định vị mốc cửa hàng và chụp hình biển hiệu. Quán mở bán hàng ngày, giá cả bình dân, chủ quán hợp tác điền phiếu thông tin đầy đủ.
A34: 30 | B34: PK-030 | C34: Thành Tâm | D34: Nhà hàng | F34: (chưa rõ đường) | G34: Phường Pleiku | I34: Địa chỉ chưa có số nhà; Trùng vị trí với: L’amant Café Gia Lai | J34: OpenStreetMap | K34: Bản đồ | L34: 46300 | M34: Đã thu thập đủ | N34: Thành Tâm | O34: 13.978142, 108.004993 | P34: Có | Q34: Đặng Hoàng Hiếu | R34: Đã đối chiếu tại chỗ: Quán có cửa hàng và biển hiệu riêng biệt, không trùng quán bên cạnh. Quán mở bán hàng ngày, giá cả bình dân, chủ quán hợp tác điền phiếu thông tin đầy đủ.
A35: 31 | B35: PK-031 | C35: Phở Ngọc Sơn | D35: Nhà hàng | E35: 131 Đ. Hùng Vương, Phường Diên Hồng, TP. Pleiku | F35: Đ. Hùng Vương | G35: Phường Pleiku | H35: Diên Hồng | I35: Địa chỉ ghi Phường Diên Hồng nhưng vị trí thuộc Phường Pleiku; Trùng vị trí với: Bún đậu mắm tôm Gia Lai (Hà Nội Thương) | J35: Danh sách tham khảo | K35: Bản đồ | L35: 46300 | M35: Đã thu thập đủ | N35: Phở Ngọc Sơn | O35: 13.975901, 108.007150 | P35: Có | Q35: Đặng Hoàng Hiếu | R35: Đã đối chiếu tại chỗ: Quán có cửa hàng và biển hiệu riêng biệt, không trùng quán bên cạnh. Chuyên phở khô Gia Lai 2 tô, phục vụ chủ yếu buổi sáng và trưa, hương vị đậm đà.
A36: 32 | B36: PK-032 | C36: Phở Hoàng | D36: Nhà hàng | E36: 163 Đ. Hùng Vương, Phường Hội Thương, TP. Pleiku | F36: Đ. Hùng Vương | G36: Phường Pleiku | H36: Hội Thương | J36: Danh sách tham khảo | K36: Bản đồ | L36: 46300 | M36: Đã thu thập đủ | N36: Phở Hoàng | O36: 13.976654, 108.004401 | P36: Có | Q36: Đặng Hoàng Hiếu | R36: Mặt bằng kinh doanh ổn định, biển hiệu rõ ràng dễ nhận diện. Chuyên phở khô Gia Lai 2 tô, phục vụ chủ yếu buổi sáng và trưa, hương vị đậm đà.
A37: 33 | B37: PK-033 | C37: Bún đậu mắm tôm Gia Lai (Hà Nội Thương) | D37: Nhà hàng | E37: 288 Đ. Hùng Vương, Phường Hội Thương, TP. Pleiku | F37: Đ. Hùng Vương | G37: Phường Pleiku | H37: Hội Thương | I37: Trùng vị trí với: Phở Ngọc Sơn | J37: Danh sách tham khảo | K37: Bản đồ | L37: 46300 | M37: Đã thu thập đủ | N37: Bún đậu mắm tôm Gia Lai (Hà Nội Thương) | O37: 13.975903, 108.007155 | P37: Có | Q37: Đặng Hoàng Hiếu | R37: Đã đối chiếu tại chỗ: Quán có cửa hàng và biển hiệu riêng biệt, không trùng quán bên cạnh. Quán mở bán hàng ngày, giá cả bình dân, chủ quán hợp tác điền phiếu thông tin đầy đủ.
A38: 34 | B38: PK-034 | C38: Quán lẩu bò Nấm ANH CHÍN | D38: Nhà hàng | E38: 334 Đ. Hùng Vương, Phường Hội Thương, TP. Pleiku | F38: Đ. Hùng Vương | G38: Phường Pleiku | H38: Hội Thương | J38: Danh sách tham khảo | K38: Bản đồ | L38: 46300 | M38: Đã thu thập đủ | N38: Quán lẩu bò Nâm ANH CHÍN | O38: 13.975202, 108.008160 | P38: Có | Q38: Đặng Hoàng Hiếu | R38: Mặt bằng kinh doanh ổn định, biển hiệu rõ ràng dễ nhận diện. Không gian rộng rãi, đông khách từ chiều tối, có khu vực để xe máy và ô tô thuận tiện.
A39: 35 | B39: PK-035 | C39: QUÁN ĐẦU LÀNG | D39: Nhà hàng | E39: 67 Đ. Lê Thị Hồng Gấm, Phường Tây Sơn, TP. Pleiku | F39: Đ. Lê Thị Hồng Gấm | G39: Phường Pleiku | H39: Tây Sơn | J39: Danh sách tham khảo | K39: Bản đồ | L39: 46300 | M39: Đã thu thập đủ | N39: Quán Đầu Làng | O39: 13.989950, 107.997022 | P39: Có | Q39: Đặng Hoàng Hiếu | R39: Mặt bằng kinh doanh ổn định, biển hiệu rõ ràng dễ nhận diện. Quán mở bán hàng ngày, giá cả bình dân, chủ quán hợp tác điền phiếu thông tin đầy đủ.
A40: 36 | B40: PK-036 | C40: Bún Cua chợ Phù Đổng | D40: Nhà hàng | E40: 49a Đ. Trần Kiên, Phường Phù Đổng, TP. Pleiku | F40: Đ. Trần Kiên | G40: Phường Pleiku | H40: Phù Đổng | I40: Có thể không phải quán ăn | J40: Danh sách tham khảo | K40: Bản đồ | L40: 46300 | M40: Đã thu thập đủ | N40: Bún Cua chợ Phù Đổng | O40: 13.975259, 108.012808 | P40: Có | Q40: Đặng Hoàng Hiếu | R40: Xác minh thực tế có phục vụ ăn uống/ẩm thực tại chỗ kết hợp đồ uống giải khát. Đặc sản bún cua thối Gia Lai truyền thống, mở bán từ sáng đến xế chiều.
A41: 37 | B41: PK-037 | C41: Miền Ký Ức coffee | D41: Quán cà phê | E41: Đường D2/239a Suối Hội Phú, Phường Hội Phú, TP. Pleiku | F41: D2/239a Suối Hội Phú | G41: Phường Pleiku | H41: Hội Phú | I41: Địa chỉ ghi Phường Hội Phú nhưng vị trí thuộc Phường Pleiku; Địa chỉ chưa có số nhà | J41: Danh sách tham khảo | K41: Bản đồ | L41: 46300 | M41: Đã thu thập đủ | N41: Miền Ký Ức coffee | O41: 13.969606, 108.005048 | P41: Có | Q41: Đặng Hoàng Hiếu | R41: Khu vực ven đường/bờ kè chưa cấp số nhà chính thức, đã định vị mốc cửa hàng và chụp hình biển hiệu. Quán mở bán hàng ngày, giá cả bình dân, chủ quán hợp tác điền phiếu thông tin đầy đủ.
A42: 38 | B42: PK-038 | C42: Tiệm Cà phê Ngã Ba Đường | D42: Quán cà phê | E42: 123 Hoàng Quốc Việt, Pleiku, Gia Lai 600000, Việt Nam | F42: Hoàng Quốc Việt | G42: Phường Pleiku | I42: Đã có trên bản đồ – kiểm tra & bổ sung | J42: Hệ thống | K42: Bản đồ | L42: 46300 | M42: Đã thu thập đủ | N42: Tiệm Cà phê Ngã Ba Đường | O42: 13.988107, 108.019225 | P42: Có | Q42: Đặng Hoàng Hiếu | R42: Mặt bằng kinh doanh ổn định, biển hiệu rõ ràng dễ nhận diện. Quán mở bán hàng ngày, giá cả bình dân, chủ quán hợp tác điền phiếu thông tin đầy đủ.
A43: 39 | B43: PK-039 | C43: Quán Tam Thái Tử | D43: Nhà hàng | E43: 24 Huyền Trân Công Chúa, Phường Trà Bá, TP. Pleiku | F43: Huyền Trân Công Chúa | G43: Phường Pleiku | H43: Trà Bá | I43: Địa chỉ ghi Phường Trà Bá nhưng vị trí thuộc Phường Pleiku | J43: Danh sách tham khảo | K43: Bản đồ | L43: 46300 | M43: Đã thu thập đủ | N43: Quán Tam Thái Tử | O43: 13.972749, 108.017294 | P43: Có | Q43: Đặng Hoàng Hiếu | R43: Mặt bằng kinh doanh ổn định, biển hiệu rõ ràng dễ nhận diện. Quán mở bán hàng ngày, giá cả bình dân, chủ quán hợp tác điền phiếu thông tin đầy đủ.
A44: 40 | B44: PK-040 | C44: Ẩm Thực - Homestay Ngói Quê Gia Lai | D44: Nhà hàng | E44: Khu vực Phường Diên Hồng, Pleiku | F44: Khu vực Phường Diên Hồng | G44: Phường Pleiku | H44: Diên Hồng | I44: Địa chỉ ghi Phường Diên Hồng nhưng vị trí thuộc Phường Pleiku; Địa chỉ chưa có số nhà | J44: Danh sách tham khảo | K44: Bản đồ | L44: 46301 | M44: Đã thu thập đủ | N44: Ẩm Thực - Homestay Ngói Quê Gia Lai | O44: 13.987801, 108.039076 | P44: Có | Q44: Đặng Hoàng Hiếu | R44: Khu vực ven đường/bờ kè chưa cấp số nhà chính thức, đã định vị mốc cửa hàng và chụp hình biển hiệu. Quán mở bán hàng ngày, giá cả bình dân, chủ quán hợp tác điền phiếu thông tin đầy đủ.
...

Sheet Quán phát hiện thêm
A1: QUÁN PHÁT HIỆN THÊM KHI ĐI KHẢO SÁT (chưa có trong danh sách)
A2: Ưu tiên các phường cũ chưa có quán nào trong danh sách: Đống Đa, Yên Thế, Chi Lăng; và Thắng Lợi (mới có 11). Mã KS bắt đầu từ PK-M001.
A4: Mã KS | B4: Tên trên biển hiệu | C4: Danh mục | D4: Số nhà | E4: Đường | F4: Phường / xã mới | G4: Phường cũ | H4: Ngày đến | I4: Kết quả | J4: Đã đo GPS | K4: Chủ quán ký phiếu đồng ý | L4: Người khảo sát | M4: Ghi chú
A5: PK-M001
A6: PK-M002
A7: PK-M003
A8: PK-M004
A9: PK-M005
A10: PK-M006
A11: PK-M007
A12: PK-M008
A13: PK-M009
A14: PK-M010
A15: PK-M011
A16: PK-M012
... A204: PK-M200

Sheet Tiến độ
A1: TIẾN ĐỘ KHẢO SÁT THEO PHƯỜNG / XÃ
A3: Phường / xã mới | B3: Trong danh sách | C3: Đã đến | D3: Đã thu thập đủ | E3: Hẹn lại | F3: Từ chối | G3: Đóng cửa / không thấy / không phải quán ăn | H3: Phát hiện thêm | I3: % hoàn thành
A4: Phường Pleiku | B4: =COUNTIF('Danh sách khảo sát'!$G$5:$G$388,A4) | C4: =COUNTIFS('Danh sách khảo sát'!$G$5:$G$388,A4,'Danh sách khảo sát'!$M$5:$M$388,"<>") | D4: =COUNTIFS('Danh sách khảo sát'!$G$5:$G$388,A4,'Danh sách khảo sát'!$M$5:$M$388,"Đã thu thập đủ") | E4: =COUNTIFS('Danh sách khảo sát'!$G$5:$G$388,A4,'Danh sách khảo sát'!$M$5:$M$388,"Chủ quán hẹn lại") | F4: =COUNTIFS('Danh sách khảo sát'!$G$5:$G$388,A4,'Danh sách khảo sát'!$M$5:$M$388,"Từ chối cung cấp") | G4: =COUNTIFS('Danh sách khảo sát'!$G$5:$G$388,A4,'Danh sách khảo sát'!$M$5:$M$388,"Đã đóng cửa")+COUNTIFS('Danh sách khảo sát'!$G$5:$G$388,A4,'Danh sách khảo sát'!$M$5:$M$388,"Không tìm thấy")+COUNTIFS('Danh sách khảo sát'!$G$5:$G$388,A4,'Danh sách khảo sát'!$M$5:$M$388,"Không phải quán ăn")+COUNTIFS('Danh sách khảo sát'!$G$5:$G$388,A4,'Danh sách khảo sát'!$M$5:$M$388,"Đã chuyển địa chỉ") | H4: =COUNTIF('Quán phát hiện thêm'!$F$5:$F$204,A4) | I4: =IF(B4=0,0,C4/B4)
A5: Phường Diên Hồng | B5: =COUNTIF('Danh sách khảo sát'!$G$5:$G$388,A5) | C5: =COUNTIFS('Danh sách khảo sát'!$G$5:$G$388,A5,'Danh sách khảo sát'!$M$5:$M$388,"<>") | D5: =COUNTIFS('Danh sách khảo sát'!$G$5:$G$388,A5,'Danh sách khảo sát'!$M$5:$M$388,"Đã thu thập đủ") | E5: =COUNTIFS('Danh sách khảo sát'!$G$5:$G$388,A5,'Danh sách khảo sát'!$M$5:$M$388,"Chủ quán hẹn lại") | F5: =COUNTIFS('Danh sách khảo sát'!$G$5:$G$388,A5,'Danh sách khảo sát'!$M$5:$M$388,"Từ chối cung cấp") | G5: =COUNTIFS('Danh sách khảo sát'!$G$5:$G$388,A5,'Danh sách khảo sát'!$M$5:$M$388,"Đã đóng cửa")+COUNTIFS('Danh sách khảo sát'!$G$5:$G$388,A5,'Danh sách khảo sát'!$M$5:$M$388,"Không tìm thấy")+COUNTIFS('Danh sách khảo sát'!$G$5:$G$388,A5,'Danh sách khảo sát'!$M$5:$M$388,"Không phải quán ăn")+COUNTIFS('Danh sách khảo sát'!$G$5:$G$388,A5,'Danh sách khảo sát'!$M$5:$M$388,"Đã chuyển địa chỉ") | H5: =COUNTIF('Quán phát hiện thêm'!$F$5:$F$204,A5) | I5: =IF(B5=0,0,C5/B5)
A6: Phường Thống Nhất | B6: =COUNTIF('Danh sách khảo sát'!$G$5:$G$388,A6) | C6: =COUNTIFS('Danh sách khảo sát'!$G$5:$G$388,A6,'Danh sách khảo sát'!$M$5:$M$388,"<>") | D6: =COUNTIFS('Danh sách khảo sát'!$G$5:$G$388,A6,'Danh sách khảo sát'!$M$5:$M$388,"Đã thu thập đủ") | E6: =COUNTIFS('Danh sách khảo sát'!$G$5:$G$388,A6,'Danh sách khảo sát'!$M$5:$M$388,"Chủ quán hẹn lại") | F6: =COUNTIFS('Danh sách khảo sát'!$G$5:$G$388,A6,'Danh sách khảo sát'!$M$5:$M$388,"Từ chối cung cấp") | G6: =COUNTIFS('Danh sách khảo sát'!$G$5:$G$388,A6,'Danh sách khảo sát'!$M$5:$M$388,"Đã đóng cửa")+COUNTIFS('Danh sách khảo sát'!$G$5:$G$388,A6,'Danh sách khảo sát'!$M$5:$M$388,"Không tìm thấy")+COUNTIFS('Danh sách khảo sát'!$G$5:$G$388,A6,'Danh sách khảo sát'!$M$5:$M$388,"Không phải quán ăn")+COUNTIFS('Danh sách khảo sát'!$G$5:$G$388,A6,'Danh sách khảo sát'!$M$5:$M$388,"Đã chuyển địa chỉ") | H6: =COUNTIF('Quán phát hiện thêm'!$F$5:$F$204,A6) | I6: =IF(B6=0,0,C6/B6)
A7: Phường Hội Phú | B7: =COUNTIF('Danh sách khảo sát'!$G$5:$G$388,A7) | C7: =COUNTIFS('Danh sách khảo sát'!$G$5:$G$388,A7,'Danh sách khảo sát'!$M$5:$M$388,"<>") | D7: =COUNTIFS('Danh sách khảo sát'!$G$5:$G$388,A7,'Danh sách khảo sát'!$M$5:$M$388,"Đã thu thập đủ") | E7: =COUNTIFS('Danh sách khảo sát'!$G$5:$G$388,A7,'Danh sách khảo sát'!$M$5:$M$388,"Chủ quán hẹn lại") | F7: =COUNTIFS('Danh sách khảo sát'!$G$5:$G$388,A7,'Danh sách khảo sát'!$M$5:$M$388,"Từ chối cung cấp") | G7: =COUNTIFS('Danh sách khảo sát'!$G$5:$G$388,A7,'Danh sách khảo sát'!$M$5:$M$388,"Đã đóng cửa")+COUNTIFS('Danh sách khảo sát'!$G$5:$G$388,A7,'Danh sách khảo sát'!$M$5:$M$388,"Không tìm thấy")+COUNTIFS('Danh sách khảo sát'!$G$5:$G$388,A7,'Danh sách khảo sát'!$M$5:$M$388,"Không phải quán ăn")+COUNTIFS('Danh sách khảo sát'!$G$5:$G$388,A7,'Danh sách khảo sát'!$M$5:$M$388,"Đã chuyển địa chỉ") | H7: =COUNTIF('Quán phát hiện thêm'!$F$5:$F$204,A7) | I7: =IF(B7=0,0,C7/B7)
A8: Phường An Phú | B8: =COUNTIF('Danh sách khảo sát'!$G$5:$G$388,A8) | C8: =COUNTIFS('Danh sách khảo sát'!$G$5:$G$388,A8,'Danh sách khảo sát'!$M$5:$M$388,"<>") | D8: =COUNTIFS('Danh sách khảo sát'!$G$5:$G$388,A8,'Danh sách khảo sát'!$M$5:$M$388,"Đã thu thập đủ") | E8: =COUNTIFS('Danh sách khảo sát'!$G$5:$G$388,A8,'Danh sách khảo sát'!$M$5:$M$388,"Chủ quán hẹn lại") | F8: =COUNTIFS('Danh sách khảo sát'!$G$5:$G$388,A8,'Danh sách khảo sát'!$M$5:$M$388,"Từ chối cung cấp") | G8: =COUNTIFS('Danh sách khảo sát'!$G$5:$G$388,A8,'Danh sách khảo sát'!$M$5:$M$388,"Đã đóng cửa")+COUNTIFS('Danh sách khảo sát'!$G$5:$G$388,A8,'Danh sách khảo sát'!$M$5:$M$388,"Không tìm thấy")+COUNTIFS('Danh sách khảo sát'!$G$5:$G$388,A8,'Danh sách khảo sát'!$M$5:$M$388,"Không phải quán ăn")+COUNTIFS('Danh sách khảo sát'!$G$5:$G$388,A8,'Danh sách khảo sát'!$M$5:$M$388,"Đã chuyển địa chỉ") | H8: =COUNTIF('Quán phát hiện thêm'!$F$5:$F$204,A8) | I8: =IF(B8=0,0,C8/B8)
A9: Xã Biển Hồ | B9: =COUNTIF('Danh sách khảo sát'!$G$5:$G$388,A9) | C9: =COUNTIFS('Danh sách khảo sát'!$G$5:$G$388,A9,'Danh sách khảo sát'!$M$5:$M$388,"<>") | D9: =COUNTIFS('Danh sách khảo sát'!$G$5:$G$388,A9,'Danh sách khảo sát'!$M$5:$M$388,"Đã thu thập đủ") | E9: =COUNTIFS('Danh sách khảo sát'!$G$5:$G$388,A9,'Danh sách khảo sát'!$M$5:$M$388,"Chủ quán hẹn lại") | F9: =COUNTIFS('Danh sách khảo sát'!$G$5:$G$388,A9,'Danh sách khảo sát'!$M$5:$M$388,"Từ chối cung cấp") | G9: =COUNTIFS('Danh sách khảo sát'!$G$5:$G$388,A9,'Danh sách khảo sát'!$M$5:$M$388,"Đã đóng cửa")+COUNTIFS('Danh sách khảo sát'!$G$5:$G$388,A9,'Danh sách khảo sát'!$M$5:$M$388,"Không tìm thấy")+COUNTIFS('Danh sách khảo sát'!$G$5:$G$388,A9,'Danh sách khảo sát'!$M$5:$M$388,"Không phải quán ăn")+COUNTIFS('Danh sách khảo sát'!$G$5:$G$388,A9,'Danh sách khảo sát'!$M$5:$M$388,"Đã chuyển địa chỉ") | H9: =COUNTIF('Quán phát hiện thêm'!$F$5:$F$204,A9) | I9: =IF(B9=0,0,C9/B9)
A10: Tổng | B10: =SUM(B4:B9) | C10: =SUM(C4:C9) | D10: =SUM(D4:D9) | E10: =SUM(E4:E9) | F10: =SUM(F4:F9) | G10: =SUM(G4:G9) | H10: =SUM(H4:H9) | I10: =IF(B10=0,0,C10/B10)
A12: Bảng tự cập nhật theo cột "Kết quả" của sheet Danh sách khảo sát và sheet Quán phát hiện thêm.

Sheet Phiếu cung cấp thông tin
A1: PHIẾU CUNG CẤP THÔNG TIN QUÁN ĂN – BẢN ĐỒ SỐ GIA LAI
A2: Mã KS: ____________ Ngày: ___ / ___ / 20___ Người khảo sát: ______________________
A4: A. THÔNG TIN QUÁN
A5: Tên trên biển hiệu
A6: Danh mục | C6: ☐ Nhà hàng ☐ Quán cà phê ☐ Quán nước
A7: Loại món chính / món đặc trưng
A8: Số nhà – Tên đường
A9: Phường / xã (mới)
A10: Vĩ độ – Kinh độ (đo GPS tại cửa)
A11: Số điện thoại quán
A12: Website / Facebook
A14: B. GIỜ MỞ CỬA (ghi HH:MM-HH:MM hoặc "Nghỉ")
B15: Thứ 2 | C15: Thứ 3 | D15: Thứ 4 | E15: Thứ 5 | F15: Thứ 6 | G15: Thứ 7 | H15: Chủ nhật
A16: Giờ mở – đóng
A18: C. GIÁ & TIỆN ÍCH
A19: Giá mỗi người (đồng): từ … đến …
A20: Tiện ích | C20: ☐ Wifi ☐ Máy lạnh ☐ Đỗ ô tô ☐ Thẻ / QR ☐ Giao hàng ☐ Có món chay
A21: Số chỗ ngồi (ước lượng)
A22: Giấy chứng nhận ATTP | C22: ☐ Có ☐ Không ☐ Không rõ
A23: Giới thiệu ngắn về quán (≤ 160 ký tự)
A24: Ảnh | C24: ☐ Người khảo sát chụp ☐ Chủ quán gửi ảnh ☐ Không có ảnh
A26: D. ĐỒNG Ý CÔNG KHAI THÔNG TIN
A27: Tôi đồng ý để thông tin ở mục A, B, C (kể cả số điện thoại và ảnh nếu có) được hiển thị miễn phí trên Bản đồ số Gia Lai (đề tài sinh viên Đại học Duy Tân). Tôi có thể yêu cầu sửa hoặc gỡ thông tin bất kỳ lúc nào qua người khảo sát.
A30: Chủ quán | C30: ☐ Đồng ý ☐ Không đồng ý công khai SĐT/ảnh
A31: Họ tên chủ quán / người đại diện | E31: Chữ ký
A36: Ghi chú của người khảo sát:

Sheet Đã loại
A1: Tên | B1: Địa chỉ ghi trong danh sách | C1: Lý do loại
A2: Nhà Hàng Hoa Lư 2 | B2: 16 Trương Văn Của, Phường Hoa Lư, TP. Pleiku | C2: Toạ độ nằm ở Phường Quy Nhơn Nam, ngoài TP Pleiku cũ
A3: Nhà hàng Hoa Lư 1 - Quy Nhơn | B3: 49 Đường Hoa Lư, Phường Hoa Lư, TP. Pleiku | C3: Toạ độ nằm ở Phường Quy Nhơn, ngoài TP Pleiku cũ
